2022-03-28 04:53:40,132 - telegram.ext.dispatcher - ERROR - No error handlers are registered, logging exception.
Traceback (most recent call last):
  File "/home/ftuser/.local/lib/python3.9/site-packages/telegram/vendor/ptb_urllib3/urllib3/connectionpool.py", line 614, in urlopen
    httplib_response = self._make_request(conn, method, url,
  File "/home/ftuser/.local/lib/python3.9/site-packages/telegram/vendor/ptb_urllib3/urllib3/connectionpool.py", line 402, in _make_request
    six.raise_from(e, None)
  File "<string>", line 2, in raise_from
  File "/home/ftuser/.local/lib/python3.9/site-packages/telegram/vendor/ptb_urllib3/urllib3/connectionpool.py", line 398, in _make_request
    httplib_response = conn.getresponse()
  File "/usr/local/lib/python3.9/http/client.py", line 1377, in getresponse
    response.begin()
  File "/usr/local/lib/python3.9/http/client.py", line 320, in begin
    version, status, reason = self._read_status()
  File "/usr/local/lib/python3.9/http/client.py", line 289, in _read_status
    raise RemoteDisconnected("Remote end closed connection without"
http.client.RemoteDisconnected: Remote end closed connection without response

During handling of the above exception, another exception occurred:

Traceback (most recent call last):
  File "/home/ftuser/.local/lib/python3.9/site-packages/telegram/utils/request.py", line 259, in _request_wrapper
    resp = self._con_pool.request(*args, **kwargs)
  File "/home/ftuser/.local/lib/python3.9/site-packages/telegram/vendor/ptb_urllib3/urllib3/request.py", line 68, in request
    return self.request_encode_body(method, url, fields=fields,
  File "/home/ftuser/.local/lib/python3.9/site-packages/telegram/vendor/ptb_urllib3/urllib3/request.py", line 148, in request_encode_body
    return self.urlopen(method, url, **extra_kw)
  File "/home/ftuser/.local/lib/python3.9/site-packages/telegram/vendor/ptb_urllib3/urllib3/poolmanager.py", line 244, in urlopen
    response = conn.urlopen(method, u.request_uri, **kw)
  File "/home/ftuser/.local/lib/python3.9/site-packages/telegram/vendor/ptb_urllib3/urllib3/connectionpool.py", line 665, in urlopen
    retries = retries.increment(method, url, error=e, _pool=self,
  File "/home/ftuser/.local/lib/python3.9/site-packages/telegram/vendor/ptb_urllib3/urllib3/util/retry.py", line 347, in increment
    raise six.reraise(type(error), error, _stacktrace)
  File "/home/ftuser/.local/lib/python3.9/site-packages/telegram/vendor/ptb_urllib3/urllib3/packages/six.py", line 685, in reraise
    raise value.with_traceback(tb)
  File "/home/ftuser/.local/lib/python3.9/site-packages/telegram/vendor/ptb_urllib3/urllib3/connectionpool.py", line 614, in urlopen
    httplib_response = self._make_request(conn, method, url,
  File "/home/ftuser/.local/lib/python3.9/site-packages/telegram/vendor/ptb_urllib3/urllib3/connectionpool.py", line 402, in _make_request
    six.raise_from(e, None)
  File "<string>", line 2, in raise_from
  File "/home/ftuser/.local/lib/python3.9/site-packages/telegram/vendor/ptb_urllib3/urllib3/connectionpool.py", line 398, in _make_request
    httplib_response = conn.getresponse()
  File "/usr/local/lib/python3.9/http/client.py", line 1377, in getresponse
    response.begin()
  File "/usr/local/lib/python3.9/http/client.py", line 320, in begin
    version, status, reason = self._read_status()
  File "/usr/local/lib/python3.9/http/client.py", line 289, in _read_status
    raise RemoteDisconnected("Remote end closed connection without"
telegram.vendor.ptb_urllib3.urllib3.exceptions.ProtocolError: ('Connection aborted.', RemoteDisconnected('Remote end closed connection without response'))

The above exception was the direct cause of the following exception:

Traceback (most recent call last):
  File "/home/ftuser/.local/lib/python3.9/site-packages/telegram/ext/updater.py", line 646, in _network_loop_retry
    if not action_cb():
  File "/home/ftuser/.local/lib/python3.9/site-packages/telegram/ext/updater.py", line 597, in polling_action_cb
    updates = self.bot.get_updates(
  File "/home/ftuser/.local/lib/python3.9/site-packages/telegram/ext/extbot.py", line 224, in get_updates
    updates = super().get_updates(
  File "/home/ftuser/.local/lib/python3.9/site-packages/telegram/bot.py", line 130, in decorator
    result = func(*args, **kwargs)
  File "/home/ftuser/.local/lib/python3.9/site-packages/telegram/bot.py", line 3054, in get_updates
    self._post(
  File "/home/ftuser/.local/lib/python3.9/site-packages/telegram/bot.py", line 295, in _post
    return self.request.post(
  File "/home/ftuser/.local/lib/python3.9/site-packages/telegram/utils/request.py", line 361, in post
    result = self._request_wrapper(
  File "/home/ftuser/.local/lib/python3.9/site-packages/telegram/utils/request.py", line 265, in _request_wrapper
    raise NetworkError(f'urllib3 HTTPError {error}') from error
telegram.error.NetworkError: urllib3 HTTPError ('Connection aborted.', RemoteDisconnected('Remote end closed connection without response'))
2022-03-28 06:07:30,752 - freqtrade.worker - INFO - Bot heartbeat. PID=1, version='2022.1', state='STOPPED'
2022-03-28 06:41:43,505 - freqtrade.worker - INFO - Bot heartbeat. PID=1, version='2022.1', state='STOPPED'
2022-03-28 06:41:51,017 - uvicorn.access - INFO - 172.20.0.1:58264 - "GET /api/v1/status HTTP/1.1" 401
2022-03-28 06:41:51,040 - uvicorn.access - INFO - 172.20.0.1:58262 - "GET /api/v1/show_config HTTP/1.1" 401
2022-03-28 06:41:51,049 - uvicorn.access - INFO - 172.20.0.1:58266 - "GET /api/v1/locks HTTP/1.1" 401
2022-03-28 06:41:51,077 - uvicorn.access - INFO - 172.20.0.1:58268 - "GET /api/v1/ping HTTP/1.1" 200
2022-03-28 06:41:51,131 - uvicorn.access - INFO - 172.20.0.1:58264 - "POST /api/v1/token/refresh HTTP/1.1" 401
2022-03-28 06:41:51,150 - uvicorn.access - INFO - 172.20.0.1:58266 - "POST /api/v1/token/refresh HTTP/1.1" 401
2022-03-28 06:41:51,162 - uvicorn.access - INFO - 172.20.0.1:58262 - "POST /api/v1/token/refresh HTTP/1.1" 401
2022-03-28 06:41:52,441 - telegram.ext.updater - ERROR - Error while getting Updates: urllib3 HTTPError ('Connection aborted.', RemoteDisconnected('Remote end closed connection without response'))
2022-03-28 06:41:52,524 - telegram.ext.dispatcher - ERROR - No error handlers are registered, logging exception.
Traceback (most recent call last):
  File "/home/ftuser/.local/lib/python3.9/site-packages/telegram/vendor/ptb_urllib3/urllib3/connectionpool.py", line 614, in urlopen
    httplib_response = self._make_request(conn, method, url,
  File "/home/ftuser/.local/lib/python3.9/site-packages/telegram/vendor/ptb_urllib3/urllib3/connectionpool.py", line 402, in _make_request
    six.raise_from(e, None)
  File "<string>", line 2, in raise_from
  File "/home/ftuser/.local/lib/python3.9/site-packages/telegram/vendor/ptb_urllib3/urllib3/connectionpool.py", line 398, in _make_request
    httplib_response = conn.getresponse()
  File "/usr/local/lib/python3.9/http/client.py", line 1377, in getresponse
    response.begin()
  File "/usr/local/lib/python3.9/http/client.py", line 320, in begin
    version, status, reason = self._read_status()
  File "/usr/local/lib/python3.9/http/client.py", line 289, in _read_status
    raise RemoteDisconnected("Remote end closed connection without"
http.client.RemoteDisconnected: Remote end closed connection without response

During handling of the above exception, another exception occurred:

Traceback (most recent call last):
  File "/home/ftuser/.local/lib/python3.9/site-packages/telegram/utils/request.py", line 259, in _request_wrapper
    resp = self._con_pool.request(*args, **kwargs)
  File "/home/ftuser/.local/lib/python3.9/site-packages/telegram/vendor/ptb_urllib3/urllib3/request.py", line 68, in request
    return self.request_encode_body(method, url, fields=fields,
  File "/home/ftuser/.local/lib/python3.9/site-packages/telegram/vendor/ptb_urllib3/urllib3/request.py", line 148, in request_encode_body
    return self.urlopen(method, url, **extra_kw)
  File "/home/ftuser/.local/lib/python3.9/site-packages/telegram/vendor/ptb_urllib3/urllib3/poolmanager.py", line 244, in urlopen
    response = conn.urlopen(method, u.request_uri, **kw)
  File "/home/ftuser/.local/lib/python3.9/site-packages/telegram/vendor/ptb_urllib3/urllib3/connectionpool.py", line 665, in urlopen
    retries = retries.increment(method, url, error=e, _pool=self,
  File "/home/ftuser/.local/lib/python3.9/site-packages/telegram/vendor/ptb_urllib3/urllib3/util/retry.py", line 347, in increment
    raise six.reraise(type(error), error, _stacktrace)
  File "/home/ftuser/.local/lib/python3.9/site-packages/telegram/vendor/ptb_urllib3/urllib3/packages/six.py", line 685, in reraise
    raise value.with_traceback(tb)
  File "/home/ftuser/.local/lib/python3.9/site-packages/telegram/vendor/ptb_urllib3/urllib3/connectionpool.py", line 614, in urlopen
    httplib_response = self._make_request(conn, method, url,
  File "/home/ftuser/.local/lib/python3.9/site-packages/telegram/vendor/ptb_urllib3/urllib3/connectionpool.py", line 402, in _make_request
    six.raise_from(e, None)
  File "<string>", line 2, in raise_from
  File "/home/ftuser/.local/lib/python3.9/site-packages/telegram/vendor/ptb_urllib3/urllib3/connectionpool.py", line 398, in _make_request
    httplib_response = conn.getresponse()
  File "/usr/local/lib/python3.9/http/client.py", line 1377, in getresponse
    response.begin()
  File "/usr/local/lib/python3.9/http/client.py", line 320, in begin
    version, status, reason = self._read_status()
  File "/usr/local/lib/python3.9/http/client.py", line 289, in _read_status
    raise RemoteDisconnected("Remote end closed connection without"
telegram.vendor.ptb_urllib3.urllib3.exceptions.ProtocolError: ('Connection aborted.', RemoteDisconnected('Remote end closed connection without response'))

The above exception was the direct cause of the following exception:

Traceback (most recent call last):
  File "/home/ftuser/.local/lib/python3.9/site-packages/telegram/ext/updater.py", line 646, in _network_loop_retry
    if not action_cb():
  File "/home/ftuser/.local/lib/python3.9/site-packages/telegram/ext/updater.py", line 597, in polling_action_cb
    updates = self.bot.get_updates(
  File "/home/ftuser/.local/lib/python3.9/site-packages/telegram/ext/extbot.py", line 224, in get_updates
    updates = super().get_updates(
  File "/home/ftuser/.local/lib/python3.9/site-packages/telegram/bot.py", line 130, in decorator
    result = func(*args, **kwargs)
  File "/home/ftuser/.local/lib/python3.9/site-packages/telegram/bot.py", line 3054, in get_updates
    self._post(
  File "/home/ftuser/.local/lib/python3.9/site-packages/telegram/bot.py", line 295, in _post
    return self.request.post(
  File "/home/ftuser/.local/lib/python3.9/site-packages/telegram/utils/request.py", line 361, in post
    result = self._request_wrapper(
  File "/home/ftuser/.local/lib/python3.9/site-packages/telegram/utils/request.py", line 265, in _request_wrapper
    raise NetworkError(f'urllib3 HTTPError {error}') from error
telegram.error.NetworkError: urllib3 HTTPError ('Connection aborted.', RemoteDisconnected('Remote end closed connection without response'))
2022-03-28 06:42:04,588 - telegram.ext.updater - ERROR - Error while getting Updates: urllib3 HTTPError ('Connection aborted.', RemoteDisconnected('Remote end closed connection without response'))
2022-03-28 06:42:04,600 - telegram.ext.dispatcher - ERROR - No error handlers are registered, logging exception.
Traceback (most recent call last):
  File "/home/ftuser/.local/lib/python3.9/site-packages/telegram/vendor/ptb_urllib3/urllib3/connectionpool.py", line 614, in urlopen
    httplib_response = self._make_request(conn, method, url,
  File "/home/ftuser/.local/lib/python3.9/site-packages/telegram/vendor/ptb_urllib3/urllib3/connectionpool.py", line 402, in _make_request
    six.raise_from(e, None)
  File "<string>", line 2, in raise_from
  File "/home/ftuser/.local/lib/python3.9/site-packages/telegram/vendor/ptb_urllib3/urllib3/connectionpool.py", line 398, in _make_request
    httplib_response = conn.getresponse()
  File "/usr/local/lib/python3.9/http/client.py", line 1377, in getresponse
    response.begin()
  File "/usr/local/lib/python3.9/http/client.py", line 320, in begin
    version, status, reason = self._read_status()
  File "/usr/local/lib/python3.9/http/client.py", line 289, in _read_status
    raise RemoteDisconnected("Remote end closed connection without"
http.client.RemoteDisconnected: Remote end closed connection without response

During handling of the above exception, another exception occurred:

Traceback (most recent call last):
  File "/home/ftuser/.local/lib/python3.9/site-packages/telegram/utils/request.py", line 259, in _request_wrapper
    resp = self._con_pool.request(*args, **kwargs)
  File "/home/ftuser/.local/lib/python3.9/site-packages/telegram/vendor/ptb_urllib3/urllib3/request.py", line 68, in request
    return self.request_encode_body(method, url, fields=fields,
  File "/home/ftuser/.local/lib/python3.9/site-packages/telegram/vendor/ptb_urllib3/urllib3/request.py", line 148, in request_encode_body
    return self.urlopen(method, url, **extra_kw)
  File "/home/ftuser/.local/lib/python3.9/site-packages/telegram/vendor/ptb_urllib3/urllib3/poolmanager.py", line 244, in urlopen
    response = conn.urlopen(method, u.request_uri, **kw)
  File "/home/ftuser/.local/lib/python3.9/site-packages/telegram/vendor/ptb_urllib3/urllib3/connectionpool.py", line 665, in urlopen
    retries = retries.increment(method, url, error=e, _pool=self,
  File "/home/ftuser/.local/lib/python3.9/site-packages/telegram/vendor/ptb_urllib3/urllib3/util/retry.py", line 347, in increment
    raise six.reraise(type(error), error, _stacktrace)
  File "/home/ftuser/.local/lib/python3.9/site-packages/telegram/vendor/ptb_urllib3/urllib3/packages/six.py", line 685, in reraise
    raise value.with_traceback(tb)
  File "/home/ftuser/.local/lib/python3.9/site-packages/telegram/vendor/ptb_urllib3/urllib3/connectionpool.py", line 614, in urlopen
    httplib_response = self._make_request(conn, method, url,
  File "/home/ftuser/.local/lib/python3.9/site-packages/telegram/vendor/ptb_urllib3/urllib3/connectionpool.py", line 402, in _make_request
    six.raise_from(e, None)
  File "<string>", line 2, in raise_from
  File "/home/ftuser/.local/lib/python3.9/site-packages/telegram/vendor/ptb_urllib3/urllib3/connectionpool.py", line 398, in _make_request
    httplib_response = conn.getresponse()
  File "/usr/local/lib/python3.9/http/client.py", line 1377, in getresponse
    response.begin()
  File "/usr/local/lib/python3.9/http/client.py", line 320, in begin
    version, status, reason = self._read_status()
  File "/usr/local/lib/python3.9/http/client.py", line 289, in _read_status
    raise RemoteDisconnected("Remote end closed connection without"
telegram.vendor.ptb_urllib3.urllib3.exceptions.ProtocolError: ('Connection aborted.', RemoteDisconnected('Remote end closed connection without response'))

The above exception was the direct cause of the following exception:

Traceback (most recent call last):
  File "/home/ftuser/.local/lib/python3.9/site-packages/telegram/ext/updater.py", line 646, in _network_loop_retry
    if not action_cb():
  File "/home/ftuser/.local/lib/python3.9/site-packages/telegram/ext/updater.py", line 597, in polling_action_cb
    updates = self.bot.get_updates(
  File "/home/ftuser/.local/lib/python3.9/site-packages/telegram/ext/extbot.py", line 224, in get_updates
    updates = super().get_updates(
  File "/home/ftuser/.local/lib/python3.9/site-packages/telegram/bot.py", line 130, in decorator
    result = func(*args, **kwargs)
  File "/home/ftuser/.local/lib/python3.9/site-packages/telegram/bot.py", line 3054, in get_updates
    self._post(
  File "/home/ftuser/.local/lib/python3.9/site-packages/telegram/bot.py", line 295, in _post
    return self.request.post(
  File "/home/ftuser/.local/lib/python3.9/site-packages/telegram/utils/request.py", line 361, in post
    result = self._request_wrapper(
  File "/home/ftuser/.local/lib/python3.9/site-packages/telegram/utils/request.py", line 265, in _request_wrapper
    raise NetworkError(f'urllib3 HTTPError {error}') from error
telegram.error.NetworkError: urllib3 HTTPError ('Connection aborted.', RemoteDisconnected('Remote end closed connection without response'))
2022-03-28 07:50:27,735 - telegram.ext.updater - ERROR - Error while getting Updates: urllib3 HTTPError ('Connection aborted.', RemoteDisconnected('Remote end closed connection without response'))
2022-03-28 07:50:27,747 - telegram.ext.dispatcher - ERROR - No error handlers are registered, logging exception.
Traceback (most recent call last):
  File "/home/ftuser/.local/lib/python3.9/site-packages/telegram/vendor/ptb_urllib3/urllib3/connectionpool.py", line 614, in urlopen
    httplib_response = self._make_request(conn, method, url,
  File "/home/ftuser/.local/lib/python3.9/site-packages/telegram/vendor/ptb_urllib3/urllib3/connectionpool.py", line 402, in _make_request
    six.raise_from(e, None)
  File "<string>", line 2, in raise_from
  File "/home/ftuser/.local/lib/python3.9/site-packages/telegram/vendor/ptb_urllib3/urllib3/connectionpool.py", line 398, in _make_request
    httplib_response = conn.getresponse()
  File "/usr/local/lib/python3.9/http/client.py", line 1377, in getresponse
    response.begin()
  File "/usr/local/lib/python3.9/http/client.py", line 320, in begin
    version, status, reason = self._read_status()
  File "/usr/local/lib/python3.9/http/client.py", line 289, in _read_status
    raise RemoteDisconnected("Remote end closed connection without"
http.client.RemoteDisconnected: Remote end closed connection without response

During handling of the above exception, another exception occurred:

Traceback (most recent call last):
  File "/home/ftuser/.local/lib/python3.9/site-packages/telegram/utils/request.py", line 259, in _request_wrapper
    resp = self._con_pool.request(*args, **kwargs)
  File "/home/ftuser/.local/lib/python3.9/site-packages/telegram/vendor/ptb_urllib3/urllib3/request.py", line 68, in request
    return self.request_encode_body(method, url, fields=fields,
  File "/home/ftuser/.local/lib/python3.9/site-packages/telegram/vendor/ptb_urllib3/urllib3/request.py", line 148, in request_encode_body
    return self.urlopen(method, url, **extra_kw)
  File "/home/ftuser/.local/lib/python3.9/site-packages/telegram/vendor/ptb_urllib3/urllib3/poolmanager.py", line 244, in urlopen
    response = conn.urlopen(method, u.request_uri, **kw)
  File "/home/ftuser/.local/lib/python3.9/site-packages/telegram/vendor/ptb_urllib3/urllib3/connectionpool.py", line 665, in urlopen
    retries = retries.increment(method, url, error=e, _pool=self,
  File "/home/ftuser/.local/lib/python3.9/site-packages/telegram/vendor/ptb_urllib3/urllib3/util/retry.py", line 347, in increment
    raise six.reraise(type(error), error, _stacktrace)
  File "/home/ftuser/.local/lib/python3.9/site-packages/telegram/vendor/ptb_urllib3/urllib3/packages/six.py", line 685, in reraise
    raise value.with_traceback(tb)
  File "/home/ftuser/.local/lib/python3.9/site-packages/telegram/vendor/ptb_urllib3/urllib3/connectionpool.py", line 614, in urlopen
    httplib_response = self._make_request(conn, method, url,
  File "/home/ftuser/.local/lib/python3.9/site-packages/telegram/vendor/ptb_urllib3/urllib3/connectionpool.py", line 402, in _make_request
    six.raise_from(e, None)
  File "<string>", line 2, in raise_from
  File "/home/ftuser/.local/lib/python3.9/site-packages/telegram/vendor/ptb_urllib3/urllib3/connectionpool.py", line 398, in _make_request
    httplib_response = conn.getresponse()
  File "/usr/local/lib/python3.9/http/client.py", line 1377, in getresponse
    response.begin()
  File "/usr/local/lib/python3.9/http/client.py", line 320, in begin
    version, status, reason = self._read_status()
  File "/usr/local/lib/python3.9/http/client.py", line 289, in _read_status
    raise RemoteDisconnected("Remote end closed connection without"
telegram.vendor.ptb_urllib3.urllib3.exceptions.ProtocolError: ('Connection aborted.', RemoteDisconnected('Remote end closed connection without response'))

The above exception was the direct cause of the following exception:

Traceback (most recent call last):
  File "/home/ftuser/.local/lib/python3.9/site-packages/telegram/ext/updater.py", line 646, in _network_loop_retry
    if not action_cb():
  File "/home/ftuser/.local/lib/python3.9/site-packages/telegram/ext/updater.py", line 597, in polling_action_cb
    updates = self.bot.get_updates(
  File "/home/ftuser/.local/lib/python3.9/site-packages/telegram/ext/extbot.py", line 224, in get_updates
    updates = super().get_updates(
  File "/home/ftuser/.local/lib/python3.9/site-packages/telegram/bot.py", line 130, in decorator
    result = func(*args, **kwargs)
  File "/home/ftuser/.local/lib/python3.9/site-packages/telegram/bot.py", line 3054, in get_updates
    self._post(
  File "/home/ftuser/.local/lib/python3.9/site-packages/telegram/bot.py", line 295, in _post
    return self.request.post(
  File "/home/ftuser/.local/lib/python3.9/site-packages/telegram/utils/request.py", line 361, in post
    result = self._request_wrapper(
  File "/home/ftuser/.local/lib/python3.9/site-packages/telegram/utils/request.py", line 265, in _request_wrapper
    raise NetworkError(f'urllib3 HTTPError {error}') from error
telegram.error.NetworkError: urllib3 HTTPError ('Connection aborted.', RemoteDisconnected('Remote end closed connection without response'))
2022-03-28 07:50:30,873 - freqtrade.worker - INFO - Bot heartbeat. PID=1, version='2022.1', state='STOPPED'
2022-03-28 07:50:48,243 - telegram.ext.updater - ERROR - Error while getting Updates: urllib3 HTTPError ('Connection aborted.', RemoteDisconnected('Remote end closed connection without response'))
2022-03-28 07:50:48,266 - telegram.ext.dispatcher - ERROR - No error handlers are registered, logging exception.
Traceback (most recent call last):
  File "/home/ftuser/.local/lib/python3.9/site-packages/telegram/vendor/ptb_urllib3/urllib3/connectionpool.py", line 614, in urlopen
    httplib_response = self._make_request(conn, method, url,
  File "/home/ftuser/.local/lib/python3.9/site-packages/telegram/vendor/ptb_urllib3/urllib3/connectionpool.py", line 402, in _make_request
    six.raise_from(e, None)
  File "<string>", line 2, in raise_from
  File "/home/ftuser/.local/lib/python3.9/site-packages/telegram/vendor/ptb_urllib3/urllib3/connectionpool.py", line 398, in _make_request
    httplib_response = conn.getresponse()
  File "/usr/local/lib/python3.9/http/client.py", line 1377, in getresponse
    response.begin()
  File "/usr/local/lib/python3.9/http/client.py", line 320, in begin
    version, status, reason = self._read_status()
  File "/usr/local/lib/python3.9/http/client.py", line 289, in _read_status
    raise RemoteDisconnected("Remote end closed connection without"
http.client.RemoteDisconnected: Remote end closed connection without response

During handling of the above exception, another exception occurred:

Traceback (most recent call last):
  File "/home/ftuser/.local/lib/python3.9/site-packages/telegram/utils/request.py", line 259, in _request_wrapper
    resp = self._con_pool.request(*args, **kwargs)
  File "/home/ftuser/.local/lib/python3.9/site-packages/telegram/vendor/ptb_urllib3/urllib3/request.py", line 68, in request
    return self.request_encode_body(method, url, fields=fields,
  File "/home/ftuser/.local/lib/python3.9/site-packages/telegram/vendor/ptb_urllib3/urllib3/request.py", line 148, in request_encode_body
    return self.urlopen(method, url, **extra_kw)
  File "/home/ftuser/.local/lib/python3.9/site-packages/telegram/vendor/ptb_urllib3/urllib3/poolmanager.py", line 244, in urlopen
    response = conn.urlopen(method, u.request_uri, **kw)
  File "/home/ftuser/.local/lib/python3.9/site-packages/telegram/vendor/ptb_urllib3/urllib3/connectionpool.py", line 665, in urlopen
    retries = retries.increment(method, url, error=e, _pool=self,
  File "/home/ftuser/.local/lib/python3.9/site-packages/telegram/vendor/ptb_urllib3/urllib3/util/retry.py", line 347, in increment
    raise six.reraise(type(error), error, _stacktrace)
  File "/home/ftuser/.local/lib/python3.9/site-packages/telegram/vendor/ptb_urllib3/urllib3/packages/six.py", line 685, in reraise
    raise value.with_traceback(tb)
  File "/home/ftuser/.local/lib/python3.9/site-packages/telegram/vendor/ptb_urllib3/urllib3/connectionpool.py", line 614, in urlopen
    httplib_response = self._make_request(conn, method, url,
  File "/home/ftuser/.local/lib/python3.9/site-packages/telegram/vendor/ptb_urllib3/urllib3/connectionpool.py", line 402, in _make_request
    six.raise_from(e, None)
  File "<string>", line 2, in raise_from
  File "/home/ftuser/.local/lib/python3.9/site-packages/telegram/vendor/ptb_urllib3/urllib3/connectionpool.py", line 398, in _make_request
    httplib_response = conn.getresponse()
  File "/usr/local/lib/python3.9/http/client.py", line 1377, in getresponse
    response.begin()
  File "/usr/local/lib/python3.9/http/client.py", line 320, in begin
    version, status, reason = self._read_status()
  File "/usr/local/lib/python3.9/http/client.py", line 289, in _read_status
    raise RemoteDisconnected("Remote end closed connection without"
telegram.vendor.ptb_urllib3.urllib3.exceptions.ProtocolError: ('Connection aborted.', RemoteDisconnected('Remote end closed connection without response'))

The above exception was the direct cause of the following exception:

Traceback (most recent call last):
  File "/home/ftuser/.local/lib/python3.9/site-packages/telegram/ext/updater.py", line 646, in _network_loop_retry
    if not action_cb():
  File "/home/ftuser/.local/lib/python3.9/site-packages/telegram/ext/updater.py", line 597, in polling_action_cb
    updates = self.bot.get_updates(
  File "/home/ftuser/.local/lib/python3.9/site-packages/telegram/ext/extbot.py", line 224, in get_updates
    updates = super().get_updates(
  File "/home/ftuser/.local/lib/python3.9/site-packages/telegram/bot.py", line 130, in decorator
    result = func(*args, **kwargs)
  File "/home/ftuser/.local/lib/python3.9/site-packages/telegram/bot.py", line 3054, in get_updates
    self._post(
  File "/home/ftuser/.local/lib/python3.9/site-packages/telegram/bot.py", line 295, in _post
    return self.request.post(
  File "/home/ftuser/.local/lib/python3.9/site-packages/telegram/utils/request.py", line 361, in post
    result = self._request_wrapper(
  File "/home/ftuser/.local/lib/python3.9/site-packages/telegram/utils/request.py", line 265, in _request_wrapper
    raise NetworkError(f'urllib3 HTTPError {error}') from error
telegram.error.NetworkError: urllib3 HTTPError ('Connection aborted.', RemoteDisconnected('Remote end closed connection without response'))
2022-03-28 08:30:04,129 - freqtrade.worker - INFO - Bot heartbeat. PID=1, version='2022.1', state='STOPPED'
2022-03-28 08:30:04,471 - telegram.ext.updater - ERROR - Error while getting Updates: urllib3 HTTPError ('Connection aborted.', RemoteDisconnected('Remote end closed connection without response'))
2022-03-28 08:30:04,486 - telegram.ext.dispatcher - ERROR - No error handlers are registered, logging exception.
Traceback (most recent call last):
  File "/home/ftuser/.local/lib/python3.9/site-packages/telegram/vendor/ptb_urllib3/urllib3/connectionpool.py", line 614, in urlopen
    httplib_response = self._make_request(conn, method, url,
  File "/home/ftuser/.local/lib/python3.9/site-packages/telegram/vendor/ptb_urllib3/urllib3/connectionpool.py", line 402, in _make_request
    six.raise_from(e, None)
  File "<string>", line 2, in raise_from
  File "/home/ftuser/.local/lib/python3.9/site-packages/telegram/vendor/ptb_urllib3/urllib3/connectionpool.py", line 398, in _make_request
    httplib_response = conn.getresponse()
  File "/usr/local/lib/python3.9/http/client.py", line 1377, in getresponse
    response.begin()
  File "/usr/local/lib/python3.9/http/client.py", line 320, in begin
    version, status, reason = self._read_status()
  File "/usr/local/lib/python3.9/http/client.py", line 289, in _read_status
    raise RemoteDisconnected("Remote end closed connection without"
http.client.RemoteDisconnected: Remote end closed connection without response

During handling of the above exception, another exception occurred:

Traceback (most recent call last):
  File "/home/ftuser/.local/lib/python3.9/site-packages/telegram/utils/request.py", line 259, in _request_wrapper
    resp = self._con_pool.request(*args, **kwargs)
  File "/home/ftuser/.local/lib/python3.9/site-packages/telegram/vendor/ptb_urllib3/urllib3/request.py", line 68, in request
    return self.request_encode_body(method, url, fields=fields,
  File "/home/ftuser/.local/lib/python3.9/site-packages/telegram/vendor/ptb_urllib3/urllib3/request.py", line 148, in request_encode_body
    return self.urlopen(method, url, **extra_kw)
  File "/home/ftuser/.local/lib/python3.9/site-packages/telegram/vendor/ptb_urllib3/urllib3/poolmanager.py", line 244, in urlopen
    response = conn.urlopen(method, u.request_uri, **kw)
  File "/home/ftuser/.local/lib/python3.9/site-packages/telegram/vendor/ptb_urllib3/urllib3/connectionpool.py", line 665, in urlopen
    retries = retries.increment(method, url, error=e, _pool=self,
  File "/home/ftuser/.local/lib/python3.9/site-packages/telegram/vendor/ptb_urllib3/urllib3/util/retry.py", line 347, in increment
    raise six.reraise(type(error), error, _stacktrace)
  File "/home/ftuser/.local/lib/python3.9/site-packages/telegram/vendor/ptb_urllib3/urllib3/packages/six.py", line 685, in reraise
    raise value.with_traceback(tb)
  File "/home/ftuser/.local/lib/python3.9/site-packages/telegram/vendor/ptb_urllib3/urllib3/connectionpool.py", line 614, in urlopen
    httplib_response = self._make_request(conn, method, url,
  File "/home/ftuser/.local/lib/python3.9/site-packages/telegram/vendor/ptb_urllib3/urllib3/connectionpool.py", line 402, in _make_request
    six.raise_from(e, None)
  File "<string>", line 2, in raise_from
  File "/home/ftuser/.local/lib/python3.9/site-packages/telegram/vendor/ptb_urllib3/urllib3/connectionpool.py", line 398, in _make_request
    httplib_response = conn.getresponse()
  File "/usr/local/lib/python3.9/http/client.py", line 1377, in getresponse
    response.begin()
  File "/usr/local/lib/python3.9/http/client.py", line 320, in begin
    version, status, reason = self._read_status()
  File "/usr/local/lib/python3.9/http/client.py", line 289, in _read_status
    raise RemoteDisconnected("Remote end closed connection without"
telegram.vendor.ptb_urllib3.urllib3.exceptions.ProtocolError: ('Connection aborted.', RemoteDisconnected('Remote end closed connection without response'))

The above exception was the direct cause of the following exception:

Traceback (most recent call last):
  File "/home/ftuser/.local/lib/python3.9/site-packages/telegram/ext/updater.py", line 646, in _network_loop_retry
    if not action_cb():
  File "/home/ftuser/.local/lib/python3.9/site-packages/telegram/ext/updater.py", line 597, in polling_action_cb
    updates = self.bot.get_updates(
  File "/home/ftuser/.local/lib/python3.9/site-packages/telegram/ext/extbot.py", line 224, in get_updates
    updates = super().get_updates(
  File "/home/ftuser/.local/lib/python3.9/site-packages/telegram/bot.py", line 130, in decorator
    result = func(*args, **kwargs)
  File "/home/ftuser/.local/lib/python3.9/site-packages/telegram/bot.py", line 3054, in get_updates
    self._post(
  File "/home/ftuser/.local/lib/python3.9/site-packages/telegram/bot.py", line 295, in _post
    return self.request.post(
  File "/home/ftuser/.local/lib/python3.9/site-packages/telegram/utils/request.py", line 361, in post
    result = self._request_wrapper(
  File "/home/ftuser/.local/lib/python3.9/site-packages/telegram/utils/request.py", line 265, in _request_wrapper
    raise NetworkError(f'urllib3 HTTPError {error}') from error
telegram.error.NetworkError: urllib3 HTTPError ('Connection aborted.', RemoteDisconnected('Remote end closed connection without response'))
2022-03-28 08:30:11,361 - telegram.ext.updater - ERROR - Error while getting Updates: urllib3 HTTPError ('Connection aborted.', RemoteDisconnected('Remote end closed connection without response'))
2022-03-28 08:30:11,418 - telegram.ext.dispatcher - ERROR - No error handlers are registered, logging exception.
Traceback (most recent call last):
  File "/home/ftuser/.local/lib/python3.9/site-packages/telegram/vendor/ptb_urllib3/urllib3/connectionpool.py", line 614, in urlopen
    httplib_response = self._make_request(conn, method, url,
  File "/home/ftuser/.local/lib/python3.9/site-packages/telegram/vendor/ptb_urllib3/urllib3/connectionpool.py", line 402, in _make_request
    six.raise_from(e, None)
  File "<string>", line 2, in raise_from
  File "/home/ftuser/.local/lib/python3.9/site-packages/telegram/vendor/ptb_urllib3/urllib3/connectionpool.py", line 398, in _make_request
    httplib_response = conn.getresponse()
  File "/usr/local/lib/python3.9/http/client.py", line 1377, in getresponse
    response.begin()
  File "/usr/local/lib/python3.9/http/client.py", line 320, in begin
    version, status, reason = self._read_status()
  File "/usr/local/lib/python3.9/http/client.py", line 289, in _read_status
    raise RemoteDisconnected("Remote end closed connection without"
http.client.RemoteDisconnected: Remote end closed connection without response

During handling of the above exception, another exception occurred:

Traceback (most recent call last):
  File "/home/ftuser/.local/lib/python3.9/site-packages/telegram/utils/request.py", line 259, in _request_wrapper
    resp = self._con_pool.request(*args, **kwargs)
  File "/home/ftuser/.local/lib/python3.9/site-packages/telegram/vendor/ptb_urllib3/urllib3/request.py", line 68, in request
    return self.request_encode_body(method, url, fields=fields,
  File "/home/ftuser/.local/lib/python3.9/site-packages/telegram/vendor/ptb_urllib3/urllib3/request.py", line 148, in request_encode_body
    return self.urlopen(method, url, **extra_kw)
  File "/home/ftuser/.local/lib/python3.9/site-packages/telegram/vendor/ptb_urllib3/urllib3/poolmanager.py", line 244, in urlopen
    response = conn.urlopen(method, u.request_uri, **kw)
  File "/home/ftuser/.local/lib/python3.9/site-packages/telegram/vendor/ptb_urllib3/urllib3/connectionpool.py", line 665, in urlopen
    retries = retries.increment(method, url, error=e, _pool=self,
  File "/home/ftuser/.local/lib/python3.9/site-packages/telegram/vendor/ptb_urllib3/urllib3/util/retry.py", line 347, in increment
    raise six.reraise(type(error), error, _stacktrace)
  File "/home/ftuser/.local/lib/python3.9/site-packages/telegram/vendor/ptb_urllib3/urllib3/packages/six.py", line 685, in reraise
    raise value.with_traceback(tb)
  File "/home/ftuser/.local/lib/python3.9/site-packages/telegram/vendor/ptb_urllib3/urllib3/connectionpool.py", line 614, in urlopen
    httplib_response = self._make_request(conn, method, url,
  File "/home/ftuser/.local/lib/python3.9/site-packages/telegram/vendor/ptb_urllib3/urllib3/connectionpool.py", line 402, in _make_request
    six.raise_from(e, None)
  File "<string>", line 2, in raise_from
  File "/home/ftuser/.local/lib/python3.9/site-packages/telegram/vendor/ptb_urllib3/urllib3/connectionpool.py", line 398, in _make_request
    httplib_response = conn.getresponse()
  File "/usr/local/lib/python3.9/http/client.py", line 1377, in getresponse
    response.begin()
  File "/usr/local/lib/python3.9/http/client.py", line 320, in begin
    version, status, reason = self._read_status()
  File "/usr/local/lib/python3.9/http/client.py", line 289, in _read_status
    raise RemoteDisconnected("Remote end closed connection without"
telegram.vendor.ptb_urllib3.urllib3.exceptions.ProtocolError: ('Connection aborted.', RemoteDisconnected('Remote end closed connection without response'))

The above exception was the direct cause of the following exception:

Traceback (most recent call last):
  File "/home/ftuser/.local/lib/python3.9/site-packages/telegram/ext/updater.py", line 646, in _network_loop_retry
    if not action_cb():
  File "/home/ftuser/.local/lib/python3.9/site-packages/telegram/ext/updater.py", line 597, in polling_action_cb
    updates = self.bot.get_updates(
  File "/home/ftuser/.local/lib/python3.9/site-packages/telegram/ext/extbot.py", line 224, in get_updates
    updates = super().get_updates(
  File "/home/ftuser/.local/lib/python3.9/site-packages/telegram/bot.py", line 130, in decorator
    result = func(*args, **kwargs)
  File "/home/ftuser/.local/lib/python3.9/site-packages/telegram/bot.py", line 3054, in get_updates
    self._post(
  File "/home/ftuser/.local/lib/python3.9/site-packages/telegram/bot.py", line 295, in _post
    return self.request.post(
  File "/home/ftuser/.local/lib/python3.9/site-packages/telegram/utils/request.py", line 361, in post
    result = self._request_wrapper(
  File "/home/ftuser/.local/lib/python3.9/site-packages/telegram/utils/request.py", line 265, in _request_wrapper
    raise NetworkError(f'urllib3 HTTPError {error}') from error
telegram.error.NetworkError: urllib3 HTTPError ('Connection aborted.', RemoteDisconnected('Remote end closed connection without response'))
2022-03-28 08:30:11,954 - uvicorn.access - INFO - 172.20.0.1:58280 - "GET /api/v1/status HTTP/1.1" 401
2022-03-28 08:30:11,982 - uvicorn.access - INFO - 172.20.0.1:58282 - "GET /api/v1/locks HTTP/1.1" 401
2022-03-28 08:30:11,996 - uvicorn.access - INFO - 172.20.0.1:58284 - "GET /api/v1/ping HTTP/1.1" 200
2022-03-28 08:30:12,005 - uvicorn.access - INFO - 172.20.0.1:58286 - "GET /api/v1/show_config HTTP/1.1" 401
2022-03-28 08:30:12,095 - uvicorn.access - INFO - 172.20.0.1:58286 - "POST /api/v1/token/refresh HTTP/1.1" 401
2022-03-28 08:30:12,101 - uvicorn.access - INFO - 172.20.0.1:58284 - "POST /api/v1/token/refresh HTTP/1.1" 401
2022-03-28 08:30:12,112 - uvicorn.access - INFO - 172.20.0.1:58282 - "POST /api/v1/token/refresh HTTP/1.1" 401
2022-03-28 08:30:23,374 - telegram.ext.updater - ERROR - Error while getting Updates: urllib3 HTTPError ('Connection aborted.', RemoteDisconnected('Remote end closed connection without response'))
2022-03-28 08:30:23,416 - telegram.ext.dispatcher - ERROR - No error handlers are registered, logging exception.
Traceback (most recent call last):
  File "/home/ftuser/.local/lib/python3.9/site-packages/telegram/vendor/ptb_urllib3/urllib3/connectionpool.py", line 614, in urlopen
    httplib_response = self._make_request(conn, method, url,
  File "/home/ftuser/.local/lib/python3.9/site-packages/telegram/vendor/ptb_urllib3/urllib3/connectionpool.py", line 402, in _make_request
    six.raise_from(e, None)
  File "<string>", line 2, in raise_from
  File "/home/ftuser/.local/lib/python3.9/site-packages/telegram/vendor/ptb_urllib3/urllib3/connectionpool.py", line 398, in _make_request
    httplib_response = conn.getresponse()
  File "/usr/local/lib/python3.9/http/client.py", line 1377, in getresponse
    response.begin()
  File "/usr/local/lib/python3.9/http/client.py", line 320, in begin
    version, status, reason = self._read_status()
  File "/usr/local/lib/python3.9/http/client.py", line 289, in _read_status
    raise RemoteDisconnected("Remote end closed connection without"
http.client.RemoteDisconnected: Remote end closed connection without response

During handling of the above exception, another exception occurred:

Traceback (most recent call last):
  File "/home/ftuser/.local/lib/python3.9/site-packages/telegram/utils/request.py", line 259, in _request_wrapper
    resp = self._con_pool.request(*args, **kwargs)
  File "/home/ftuser/.local/lib/python3.9/site-packages/telegram/vendor/ptb_urllib3/urllib3/request.py", line 68, in request
    return self.request_encode_body(method, url, fields=fields,
  File "/home/ftuser/.local/lib/python3.9/site-packages/telegram/vendor/ptb_urllib3/urllib3/request.py", line 148, in request_encode_body
    return self.urlopen(method, url, **extra_kw)
  File "/home/ftuser/.local/lib/python3.9/site-packages/telegram/vendor/ptb_urllib3/urllib3/poolmanager.py", line 244, in urlopen
    response = conn.urlopen(method, u.request_uri, **kw)
  File "/home/ftuser/.local/lib/python3.9/site-packages/telegram/vendor/ptb_urllib3/urllib3/connectionpool.py", line 665, in urlopen
    retries = retries.increment(method, url, error=e, _pool=self,
  File "/home/ftuser/.local/lib/python3.9/site-packages/telegram/vendor/ptb_urllib3/urllib3/util/retry.py", line 347, in increment
    raise six.reraise(type(error), error, _stacktrace)
  File "/home/ftuser/.local/lib/python3.9/site-packages/telegram/vendor/ptb_urllib3/urllib3/packages/six.py", line 685, in reraise
    raise value.with_traceback(tb)
  File "/home/ftuser/.local/lib/python3.9/site-packages/telegram/vendor/ptb_urllib3/urllib3/connectionpool.py", line 614, in urlopen
    httplib_response = self._make_request(conn, method, url,
  File "/home/ftuser/.local/lib/python3.9/site-packages/telegram/vendor/ptb_urllib3/urllib3/connectionpool.py", line 402, in _make_request
    six.raise_from(e, None)
  File "<string>", line 2, in raise_from
  File "/home/ftuser/.local/lib/python3.9/site-packages/telegram/vendor/ptb_urllib3/urllib3/connectionpool.py", line 398, in _make_request
    httplib_response = conn.getresponse()
  File "/usr/local/lib/python3.9/http/client.py", line 1377, in getresponse
    response.begin()
  File "/usr/local/lib/python3.9/http/client.py", line 320, in begin
    version, status, reason = self._read_status()
  File "/usr/local/lib/python3.9/http/client.py", line 289, in _read_status
    raise RemoteDisconnected("Remote end closed connection without"
telegram.vendor.ptb_urllib3.urllib3.exceptions.ProtocolError: ('Connection aborted.', RemoteDisconnected('Remote end closed connection without response'))

The above exception was the direct cause of the following exception:

Traceback (most recent call last):
  File "/home/ftuser/.local/lib/python3.9/site-packages/telegram/ext/updater.py", line 646, in _network_loop_retry
    if not action_cb():
  File "/home/ftuser/.local/lib/python3.9/site-packages/telegram/ext/updater.py", line 597, in polling_action_cb
    updates = self.bot.get_updates(
  File "/home/ftuser/.local/lib/python3.9/site-packages/telegram/ext/extbot.py", line 224, in get_updates
    updates = super().get_updates(
  File "/home/ftuser/.local/lib/python3.9/site-packages/telegram/bot.py", line 130, in decorator
    result = func(*args, **kwargs)
  File "/home/ftuser/.local/lib/python3.9/site-packages/telegram/bot.py", line 3054, in get_updates
    self._post(
  File "/home/ftuser/.local/lib/python3.9/site-packages/telegram/bot.py", line 295, in _post
    return self.request.post(
  File "/home/ftuser/.local/lib/python3.9/site-packages/telegram/utils/request.py", line 361, in post
    result = self._request_wrapper(
  File "/home/ftuser/.local/lib/python3.9/site-packages/telegram/utils/request.py", line 265, in _request_wrapper
    raise NetworkError(f'urllib3 HTTPError {error}') from error
telegram.error.NetworkError: urllib3 HTTPError ('Connection aborted.', RemoteDisconnected('Remote end closed connection without response'))
2022-03-28 09:53:55,263 - freqtrade.worker - INFO - Bot heartbeat. PID=1, version='2022.1', state='STOPPED'
2022-03-28 09:54:02,733 - telegram.ext.updater - ERROR - Error while getting Updates: urllib3 HTTPError ('Connection aborted.', RemoteDisconnected('Remote end closed connection without response'))
2022-03-28 09:54:02,762 - telegram.ext.dispatcher - ERROR - No error handlers are registered, logging exception.
Traceback (most recent call last):
  File "/home/ftuser/.local/lib/python3.9/site-packages/telegram/vendor/ptb_urllib3/urllib3/connectionpool.py", line 614, in urlopen
    httplib_response = self._make_request(conn, method, url,
  File "/home/ftuser/.local/lib/python3.9/site-packages/telegram/vendor/ptb_urllib3/urllib3/connectionpool.py", line 402, in _make_request
    six.raise_from(e, None)
  File "<string>", line 2, in raise_from
  File "/home/ftuser/.local/lib/python3.9/site-packages/telegram/vendor/ptb_urllib3/urllib3/connectionpool.py", line 398, in _make_request
    httplib_response = conn.getresponse()
  File "/usr/local/lib/python3.9/http/client.py", line 1377, in getresponse
    response.begin()
  File "/usr/local/lib/python3.9/http/client.py", line 320, in begin
    version, status, reason = self._read_status()
  File "/usr/local/lib/python3.9/http/client.py", line 289, in _read_status
    raise RemoteDisconnected("Remote end closed connection without"
http.client.RemoteDisconnected: Remote end closed connection without response

During handling of the above exception, another exception occurred:

Traceback (most recent call last):
  File "/home/ftuser/.local/lib/python3.9/site-packages/telegram/utils/request.py", line 259, in _request_wrapper
    resp = self._con_pool.request(*args, **kwargs)
  File "/home/ftuser/.local/lib/python3.9/site-packages/telegram/vendor/ptb_urllib3/urllib3/request.py", line 68, in request
    return self.request_encode_body(method, url, fields=fields,
  File "/home/ftuser/.local/lib/python3.9/site-packages/telegram/vendor/ptb_urllib3/urllib3/request.py", line 148, in request_encode_body
    return self.urlopen(method, url, **extra_kw)
  File "/home/ftuser/.local/lib/python3.9/site-packages/telegram/vendor/ptb_urllib3/urllib3/poolmanager.py", line 244, in urlopen
    response = conn.urlopen(method, u.request_uri, **kw)
  File "/home/ftuser/.local/lib/python3.9/site-packages/telegram/vendor/ptb_urllib3/urllib3/connectionpool.py", line 665, in urlopen
    retries = retries.increment(method, url, error=e, _pool=self,
  File "/home/ftuser/.local/lib/python3.9/site-packages/telegram/vendor/ptb_urllib3/urllib3/util/retry.py", line 347, in increment
    raise six.reraise(type(error), error, _stacktrace)
  File "/home/ftuser/.local/lib/python3.9/site-packages/telegram/vendor/ptb_urllib3/urllib3/packages/six.py", line 685, in reraise
    raise value.with_traceback(tb)
  File "/home/ftuser/.local/lib/python3.9/site-packages/telegram/vendor/ptb_urllib3/urllib3/connectionpool.py", line 614, in urlopen
    httplib_response = self._make_request(conn, method, url,
  File "/home/ftuser/.local/lib/python3.9/site-packages/telegram/vendor/ptb_urllib3/urllib3/connectionpool.py", line 402, in _make_request
    six.raise_from(e, None)
  File "<string>", line 2, in raise_from
  File "/home/ftuser/.local/lib/python3.9/site-packages/telegram/vendor/ptb_urllib3/urllib3/connectionpool.py", line 398, in _make_request
    httplib_response = conn.getresponse()
  File "/usr/local/lib/python3.9/http/client.py", line 1377, in getresponse
    response.begin()
  File "/usr/local/lib/python3.9/http/client.py", line 320, in begin
    version, status, reason = self._read_status()
  File "/usr/local/lib/python3.9/http/client.py", line 289, in _read_status
    raise RemoteDisconnected("Remote end closed connection without"
telegram.vendor.ptb_urllib3.urllib3.exceptions.ProtocolError: ('Connection aborted.', RemoteDisconnected('Remote end closed connection without response'))

The above exception was the direct cause of the following exception:

Traceback (most recent call last):
  File "/home/ftuser/.local/lib/python3.9/site-packages/telegram/ext/updater.py", line 646, in _network_loop_retry
    if not action_cb():
  File "/home/ftuser/.local/lib/python3.9/site-packages/telegram/ext/updater.py", line 597, in polling_action_cb
    updates = self.bot.get_updates(
  File "/home/ftuser/.local/lib/python3.9/site-packages/telegram/ext/extbot.py", line 224, in get_updates
    updates = super().get_updates(
  File "/home/ftuser/.local/lib/python3.9/site-packages/telegram/bot.py", line 130, in decorator
    result = func(*args, **kwargs)
  File "/home/ftuser/.local/lib/python3.9/site-packages/telegram/bot.py", line 3054, in get_updates
    self._post(
  File "/home/ftuser/.local/lib/python3.9/site-packages/telegram/bot.py", line 295, in _post
    return self.request.post(
  File "/home/ftuser/.local/lib/python3.9/site-packages/telegram/utils/request.py", line 361, in post
    result = self._request_wrapper(
  File "/home/ftuser/.local/lib/python3.9/site-packages/telegram/utils/request.py", line 265, in _request_wrapper
    raise NetworkError(f'urllib3 HTTPError {error}') from error
telegram.error.NetworkError: urllib3 HTTPError ('Connection aborted.', RemoteDisconnected('Remote end closed connection without response'))
2022-03-28 11:15:39,039 - freqtrade.worker - INFO - Bot heartbeat. PID=1, version='2022.1', state='STOPPED'
2022-03-28 11:15:46,337 - uvicorn.access - INFO - 172.20.0.1:58298 - "GET /api/v1/locks HTTP/1.1" 401
2022-03-28 11:15:46,391 - uvicorn.access - INFO - 172.20.0.1:58294 - "GET /api/v1/status HTTP/1.1" 401
2022-03-28 11:15:46,422 - uvicorn.access - INFO - 172.20.0.1:58300 - "GET /api/v1/show_config HTTP/1.1" 401
2022-03-28 11:15:46,444 - uvicorn.access - INFO - 172.20.0.1:58296 - "GET /api/v1/ping HTTP/1.1" 200
2022-03-28 11:15:46,466 - uvicorn.access - INFO - 172.20.0.1:58298 - "POST /api/v1/token/refresh HTTP/1.1" 401
2022-03-28 11:15:46,484 - uvicorn.access - INFO - 172.20.0.1:58294 - "POST /api/v1/token/refresh HTTP/1.1" 401
2022-03-28 11:15:46,490 - uvicorn.access - INFO - 172.20.0.1:58300 - "POST /api/v1/token/refresh HTTP/1.1" 401
2022-03-28 11:15:48,048 - telegram.ext.updater - ERROR - Error while getting Updates: urllib3 HTTPError ('Connection aborted.', RemoteDisconnected('Remote end closed connection without response'))
2022-03-28 11:15:48,064 - telegram.ext.dispatcher - ERROR - No error handlers are registered, logging exception.
Traceback (most recent call last):
  File "/home/ftuser/.local/lib/python3.9/site-packages/telegram/vendor/ptb_urllib3/urllib3/connectionpool.py", line 614, in urlopen
    httplib_response = self._make_request(conn, method, url,
  File "/home/ftuser/.local/lib/python3.9/site-packages/telegram/vendor/ptb_urllib3/urllib3/connectionpool.py", line 402, in _make_request
    six.raise_from(e, None)
  File "<string>", line 2, in raise_from
  File "/home/ftuser/.local/lib/python3.9/site-packages/telegram/vendor/ptb_urllib3/urllib3/connectionpool.py", line 398, in _make_request
    httplib_response = conn.getresponse()
  File "/usr/local/lib/python3.9/http/client.py", line 1377, in getresponse
    response.begin()
  File "/usr/local/lib/python3.9/http/client.py", line 320, in begin
    version, status, reason = self._read_status()
  File "/usr/local/lib/python3.9/http/client.py", line 289, in _read_status
    raise RemoteDisconnected("Remote end closed connection without"
http.client.RemoteDisconnected: Remote end closed connection without response

During handling of the above exception, another exception occurred:

Traceback (most recent call last):
  File "/home/ftuser/.local/lib/python3.9/site-packages/telegram/utils/request.py", line 259, in _request_wrapper
    resp = self._con_pool.request(*args, **kwargs)
  File "/home/ftuser/.local/lib/python3.9/site-packages/telegram/vendor/ptb_urllib3/urllib3/request.py", line 68, in request
    return self.request_encode_body(method, url, fields=fields,
  File "/home/ftuser/.local/lib/python3.9/site-packages/telegram/vendor/ptb_urllib3/urllib3/request.py", line 148, in request_encode_body
    return self.urlopen(method, url, **extra_kw)
  File "/home/ftuser/.local/lib/python3.9/site-packages/telegram/vendor/ptb_urllib3/urllib3/poolmanager.py", line 244, in urlopen
    response = conn.urlopen(method, u.request_uri, **kw)
  File "/home/ftuser/.local/lib/python3.9/site-packages/telegram/vendor/ptb_urllib3/urllib3/connectionpool.py", line 665, in urlopen
    retries = retries.increment(method, url, error=e, _pool=self,
  File "/home/ftuser/.local/lib/python3.9/site-packages/telegram/vendor/ptb_urllib3/urllib3/util/retry.py", line 347, in increment
    raise six.reraise(type(error), error, _stacktrace)
  File "/home/ftuser/.local/lib/python3.9/site-packages/telegram/vendor/ptb_urllib3/urllib3/packages/six.py", line 685, in reraise
    raise value.with_traceback(tb)
  File "/home/ftuser/.local/lib/python3.9/site-packages/telegram/vendor/ptb_urllib3/urllib3/connectionpool.py", line 614, in urlopen
    httplib_response = self._make_request(conn, method, url,
  File "/home/ftuser/.local/lib/python3.9/site-packages/telegram/vendor/ptb_urllib3/urllib3/connectionpool.py", line 402, in _make_request
    six.raise_from(e, None)
  File "<string>", line 2, in raise_from
  File "/home/ftuser/.local/lib/python3.9/site-packages/telegram/vendor/ptb_urllib3/urllib3/connectionpool.py", line 398, in _make_request
    httplib_response = conn.getresponse()
  File "/usr/local/lib/python3.9/http/client.py", line 1377, in getresponse
    response.begin()
  File "/usr/local/lib/python3.9/http/client.py", line 320, in begin
    version, status, reason = self._read_status()
  File "/usr/local/lib/python3.9/http/client.py", line 289, in _read_status
    raise RemoteDisconnected("Remote end closed connection without"
telegram.vendor.ptb_urllib3.urllib3.exceptions.ProtocolError: ('Connection aborted.', RemoteDisconnected('Remote end closed connection without response'))

The above exception was the direct cause of the following exception:

Traceback (most recent call last):
  File "/home/ftuser/.local/lib/python3.9/site-packages/telegram/ext/updater.py", line 646, in _network_loop_retry
    if not action_cb():
  File "/home/ftuser/.local/lib/python3.9/site-packages/telegram/ext/updater.py", line 597, in polling_action_cb
    updates = self.bot.get_updates(
  File "/home/ftuser/.local/lib/python3.9/site-packages/telegram/ext/extbot.py", line 224, in get_updates
    updates = super().get_updates(
  File "/home/ftuser/.local/lib/python3.9/site-packages/telegram/bot.py", line 130, in decorator
    result = func(*args, **kwargs)
  File "/home/ftuser/.local/lib/python3.9/site-packages/telegram/bot.py", line 3054, in get_updates
    self._post(
  File "/home/ftuser/.local/lib/python3.9/site-packages/telegram/bot.py", line 295, in _post
    return self.request.post(
  File "/home/ftuser/.local/lib/python3.9/site-packages/telegram/utils/request.py", line 361, in post
    result = self._request_wrapper(
  File "/home/ftuser/.local/lib/python3.9/site-packages/telegram/utils/request.py", line 265, in _request_wrapper
    raise NetworkError(f'urllib3 HTTPError {error}') from error
telegram.error.NetworkError: urllib3 HTTPError ('Connection aborted.', RemoteDisconnected('Remote end closed connection without response'))
2022-03-28 12:17:36,961 - freqtrade.worker - INFO - Bot heartbeat. PID=1, version='2022.1', state='STOPPED'
2022-03-28 12:17:42,359 - telegram.ext.updater - ERROR - Error while getting Updates: urllib3 HTTPError EOF occurred in violation of protocol (_ssl.c:1129)
2022-03-28 12:17:42,409 - telegram.ext.dispatcher - ERROR - No error handlers are registered, logging exception.
Traceback (most recent call last):
  File "/home/ftuser/.local/lib/python3.9/site-packages/telegram/vendor/ptb_urllib3/urllib3/connectionpool.py", line 614, in urlopen
    httplib_response = self._make_request(conn, method, url,
  File "/home/ftuser/.local/lib/python3.9/site-packages/telegram/vendor/ptb_urllib3/urllib3/connectionpool.py", line 360, in _make_request
    self._validate_conn(conn)
  File "/home/ftuser/.local/lib/python3.9/site-packages/telegram/vendor/ptb_urllib3/urllib3/connectionpool.py", line 857, in _validate_conn
    super(HTTPSConnectionPool, self)._validate_conn(conn)
  File "/home/ftuser/.local/lib/python3.9/site-packages/telegram/vendor/ptb_urllib3/urllib3/connectionpool.py", line 289, in _validate_conn
    conn.connect()
  File "/home/ftuser/.local/lib/python3.9/site-packages/telegram/vendor/ptb_urllib3/urllib3/connection.py", line 319, in connect
    self.sock = ssl_wrap_socket(
  File "/home/ftuser/.local/lib/python3.9/site-packages/telegram/vendor/ptb_urllib3/urllib3/util/ssl_.py", line 324, in ssl_wrap_socket
    return context.wrap_socket(sock, server_hostname=server_hostname)
  File "/usr/local/lib/python3.9/ssl.py", line 500, in wrap_socket
    return self.sslsocket_class._create(
  File "/usr/local/lib/python3.9/ssl.py", line 1040, in _create
    self.do_handshake()
  File "/usr/local/lib/python3.9/ssl.py", line 1309, in do_handshake
    self._sslobj.do_handshake()
ssl.SSLEOFError: EOF occurred in violation of protocol (_ssl.c:1129)

During handling of the above exception, another exception occurred:

Traceback (most recent call last):
  File "/home/ftuser/.local/lib/python3.9/site-packages/telegram/utils/request.py", line 259, in _request_wrapper
    resp = self._con_pool.request(*args, **kwargs)
  File "/home/ftuser/.local/lib/python3.9/site-packages/telegram/vendor/ptb_urllib3/urllib3/request.py", line 68, in request
    return self.request_encode_body(method, url, fields=fields,
  File "/home/ftuser/.local/lib/python3.9/site-packages/telegram/vendor/ptb_urllib3/urllib3/request.py", line 148, in request_encode_body
    return self.urlopen(method, url, **extra_kw)
  File "/home/ftuser/.local/lib/python3.9/site-packages/telegram/vendor/ptb_urllib3/urllib3/poolmanager.py", line 244, in urlopen
    response = conn.urlopen(method, u.request_uri, **kw)
  File "/home/ftuser/.local/lib/python3.9/site-packages/telegram/vendor/ptb_urllib3/urllib3/connectionpool.py", line 647, in urlopen
    raise SSLError(e)
telegram.vendor.ptb_urllib3.urllib3.exceptions.SSLError: EOF occurred in violation of protocol (_ssl.c:1129)

The above exception was the direct cause of the following exception:

Traceback (most recent call last):
  File "/home/ftuser/.local/lib/python3.9/site-packages/telegram/ext/updater.py", line 646, in _network_loop_retry
    if not action_cb():
  File "/home/ftuser/.local/lib/python3.9/site-packages/telegram/ext/updater.py", line 597, in polling_action_cb
    updates = self.bot.get_updates(
  File "/home/ftuser/.local/lib/python3.9/site-packages/telegram/ext/extbot.py", line 224, in get_updates
    updates = super().get_updates(
  File "/home/ftuser/.local/lib/python3.9/site-packages/telegram/bot.py", line 130, in decorator
    result = func(*args, **kwargs)
  File "/home/ftuser/.local/lib/python3.9/site-packages/telegram/bot.py", line 3054, in get_updates
    self._post(
  File "/home/ftuser/.local/lib/python3.9/site-packages/telegram/bot.py", line 295, in _post
    return self.request.post(
  File "/home/ftuser/.local/lib/python3.9/site-packages/telegram/utils/request.py", line 361, in post
    result = self._request_wrapper(
  File "/home/ftuser/.local/lib/python3.9/site-packages/telegram/utils/request.py", line 265, in _request_wrapper
    raise NetworkError(f'urllib3 HTTPError {error}') from error
telegram.error.NetworkError: urllib3 HTTPError EOF occurred in violation of protocol (_ssl.c:1129)
2022-03-28 13:32:54,834 - freqtrade.worker - INFO - Bot heartbeat. PID=1, version='2022.1', state='STOPPED'
2022-03-28 13:33:01,483 - uvicorn.access - INFO - 172.20.0.1:58308 - "GET /api/v1/locks HTTP/1.1" 401
2022-03-28 13:33:01,514 - uvicorn.access - INFO - 172.20.0.1:58306 - "GET /api/v1/show_config HTTP/1.1" 401
2022-03-28 13:33:01,528 - uvicorn.access - INFO - 172.20.0.1:58304 - "GET /api/v1/status HTTP/1.1" 401
2022-03-28 13:33:01,554 - uvicorn.access - INFO - 172.20.0.1:58310 - "GET /api/v1/ping HTTP/1.1" 200
2022-03-28 13:33:01,570 - uvicorn.access - INFO - 172.20.0.1:58308 - "POST /api/v1/token/refresh HTTP/1.1" 401
2022-03-28 13:33:01,581 - uvicorn.access - INFO - 172.20.0.1:58310 - "POST /api/v1/token/refresh HTTP/1.1" 401
2022-03-28 13:33:01,588 - uvicorn.access - INFO - 172.20.0.1:58304 - "POST /api/v1/token/refresh HTTP/1.1" 401
2022-03-28 13:33:12,091 - telegram.ext.updater - ERROR - Error while getting Updates: urllib3 HTTPError ('Connection aborted.', RemoteDisconnected('Remote end closed connection without response'))
2022-03-28 13:33:12,102 - telegram.ext.dispatcher - ERROR - No error handlers are registered, logging exception.
Traceback (most recent call last):
  File "/home/ftuser/.local/lib/python3.9/site-packages/telegram/vendor/ptb_urllib3/urllib3/connectionpool.py", line 614, in urlopen
    httplib_response = self._make_request(conn, method, url,
  File "/home/ftuser/.local/lib/python3.9/site-packages/telegram/vendor/ptb_urllib3/urllib3/connectionpool.py", line 402, in _make_request
    six.raise_from(e, None)
  File "<string>", line 2, in raise_from
  File "/home/ftuser/.local/lib/python3.9/site-packages/telegram/vendor/ptb_urllib3/urllib3/connectionpool.py", line 398, in _make_request
    httplib_response = conn.getresponse()
  File "/usr/local/lib/python3.9/http/client.py", line 1377, in getresponse
    response.begin()
  File "/usr/local/lib/python3.9/http/client.py", line 320, in begin
    version, status, reason = self._read_status()
  File "/usr/local/lib/python3.9/http/client.py", line 289, in _read_status
    raise RemoteDisconnected("Remote end closed connection without"
http.client.RemoteDisconnected: Remote end closed connection without response

During handling of the above exception, another exception occurred:

Traceback (most recent call last):
  File "/home/ftuser/.local/lib/python3.9/site-packages/telegram/utils/request.py", line 259, in _request_wrapper
    resp = self._con_pool.request(*args, **kwargs)
  File "/home/ftuser/.local/lib/python3.9/site-packages/telegram/vendor/ptb_urllib3/urllib3/request.py", line 68, in request
    return self.request_encode_body(method, url, fields=fields,
  File "/home/ftuser/.local/lib/python3.9/site-packages/telegram/vendor/ptb_urllib3/urllib3/request.py", line 148, in request_encode_body
    return self.urlopen(method, url, **extra_kw)
  File "/home/ftuser/.local/lib/python3.9/site-packages/telegram/vendor/ptb_urllib3/urllib3/poolmanager.py", line 244, in urlopen
    response = conn.urlopen(method, u.request_uri, **kw)
  File "/home/ftuser/.local/lib/python3.9/site-packages/telegram/vendor/ptb_urllib3/urllib3/connectionpool.py", line 665, in urlopen
    retries = retries.increment(method, url, error=e, _pool=self,
  File "/home/ftuser/.local/lib/python3.9/site-packages/telegram/vendor/ptb_urllib3/urllib3/util/retry.py", line 347, in increment
    raise six.reraise(type(error), error, _stacktrace)
  File "/home/ftuser/.local/lib/python3.9/site-packages/telegram/vendor/ptb_urllib3/urllib3/packages/six.py", line 685, in reraise
    raise value.with_traceback(tb)
  File "/home/ftuser/.local/lib/python3.9/site-packages/telegram/vendor/ptb_urllib3/urllib3/connectionpool.py", line 614, in urlopen
    httplib_response = self._make_request(conn, method, url,
  File "/home/ftuser/.local/lib/python3.9/site-packages/telegram/vendor/ptb_urllib3/urllib3/connectionpool.py", line 402, in _make_request
    six.raise_from(e, None)
  File "<string>", line 2, in raise_from
  File "/home/ftuser/.local/lib/python3.9/site-packages/telegram/vendor/ptb_urllib3/urllib3/connectionpool.py", line 398, in _make_request
    httplib_response = conn.getresponse()
  File "/usr/local/lib/python3.9/http/client.py", line 1377, in getresponse
    response.begin()
  File "/usr/local/lib/python3.9/http/client.py", line 320, in begin
    version, status, reason = self._read_status()
  File "/usr/local/lib/python3.9/http/client.py", line 289, in _read_status
    raise RemoteDisconnected("Remote end closed connection without"
telegram.vendor.ptb_urllib3.urllib3.exceptions.ProtocolError: ('Connection aborted.', RemoteDisconnected('Remote end closed connection without response'))

The above exception was the direct cause of the following exception:

Traceback (most recent call last):
  File "/home/ftuser/.local/lib/python3.9/site-packages/telegram/ext/updater.py", line 646, in _network_loop_retry
    if not action_cb():
  File "/home/ftuser/.local/lib/python3.9/site-packages/telegram/ext/updater.py", line 597, in polling_action_cb
    updates = self.bot.get_updates(
  File "/home/ftuser/.local/lib/python3.9/site-packages/telegram/ext/extbot.py", line 224, in get_updates
    updates = super().get_updates(
  File "/home/ftuser/.local/lib/python3.9/site-packages/telegram/bot.py", line 130, in decorator
    result = func(*args, **kwargs)
  File "/home/ftuser/.local/lib/python3.9/site-packages/telegram/bot.py", line 3054, in get_updates
    self._post(
  File "/home/ftuser/.local/lib/python3.9/site-packages/telegram/bot.py", line 295, in _post
    return self.request.post(
  File "/home/ftuser/.local/lib/python3.9/site-packages/telegram/utils/request.py", line 361, in post
    result = self._request_wrapper(
  File "/home/ftuser/.local/lib/python3.9/site-packages/telegram/utils/request.py", line 265, in _request_wrapper
    raise NetworkError(f'urllib3 HTTPError {error}') from error
telegram.error.NetworkError: urllib3 HTTPError ('Connection aborted.', RemoteDisconnected('Remote end closed connection without response'))
2022-03-28 14:54:18,627 - freqtrade.worker - INFO - Bot heartbeat. PID=1, version='2022.1', state='STOPPED'
2022-03-28 14:54:38,554 - telegram.ext.updater - ERROR - Error while getting Updates: urllib3 HTTPError ('Connection aborted.', RemoteDisconnected('Remote end closed connection without response'))
2022-03-28 14:54:38,572 - telegram.ext.dispatcher - ERROR - No error handlers are registered, logging exception.
Traceback (most recent call last):
  File "/home/ftuser/.local/lib/python3.9/site-packages/telegram/vendor/ptb_urllib3/urllib3/connectionpool.py", line 614, in urlopen
    httplib_response = self._make_request(conn, method, url,
  File "/home/ftuser/.local/lib/python3.9/site-packages/telegram/vendor/ptb_urllib3/urllib3/connectionpool.py", line 402, in _make_request
    six.raise_from(e, None)
  File "<string>", line 2, in raise_from
  File "/home/ftuser/.local/lib/python3.9/site-packages/telegram/vendor/ptb_urllib3/urllib3/connectionpool.py", line 398, in _make_request
    httplib_response = conn.getresponse()
  File "/usr/local/lib/python3.9/http/client.py", line 1377, in getresponse
    response.begin()
  File "/usr/local/lib/python3.9/http/client.py", line 320, in begin
    version, status, reason = self._read_status()
  File "/usr/local/lib/python3.9/http/client.py", line 289, in _read_status
    raise RemoteDisconnected("Remote end closed connection without"
http.client.RemoteDisconnected: Remote end closed connection without response

During handling of the above exception, another exception occurred:

Traceback (most recent call last):
  File "/home/ftuser/.local/lib/python3.9/site-packages/telegram/utils/request.py", line 259, in _request_wrapper
    resp = self._con_pool.request(*args, **kwargs)
  File "/home/ftuser/.local/lib/python3.9/site-packages/telegram/vendor/ptb_urllib3/urllib3/request.py", line 68, in request
    return self.request_encode_body(method, url, fields=fields,
  File "/home/ftuser/.local/lib/python3.9/site-packages/telegram/vendor/ptb_urllib3/urllib3/request.py", line 148, in request_encode_body
    return self.urlopen(method, url, **extra_kw)
  File "/home/ftuser/.local/lib/python3.9/site-packages/telegram/vendor/ptb_urllib3/urllib3/poolmanager.py", line 244, in urlopen
    response = conn.urlopen(method, u.request_uri, **kw)
  File "/home/ftuser/.local/lib/python3.9/site-packages/telegram/vendor/ptb_urllib3/urllib3/connectionpool.py", line 665, in urlopen
    retries = retries.increment(method, url, error=e, _pool=self,
  File "/home/ftuser/.local/lib/python3.9/site-packages/telegram/vendor/ptb_urllib3/urllib3/util/retry.py", line 347, in increment
    raise six.reraise(type(error), error, _stacktrace)
  File "/home/ftuser/.local/lib/python3.9/site-packages/telegram/vendor/ptb_urllib3/urllib3/packages/six.py", line 685, in reraise
    raise value.with_traceback(tb)
  File "/home/ftuser/.local/lib/python3.9/site-packages/telegram/vendor/ptb_urllib3/urllib3/connectionpool.py", line 614, in urlopen
    httplib_response = self._make_request(conn, method, url,
  File "/home/ftuser/.local/lib/python3.9/site-packages/telegram/vendor/ptb_urllib3/urllib3/connectionpool.py", line 402, in _make_request
    six.raise_from(e, None)
  File "<string>", line 2, in raise_from
  File "/home/ftuser/.local/lib/python3.9/site-packages/telegram/vendor/ptb_urllib3/urllib3/connectionpool.py", line 398, in _make_request
    httplib_response = conn.getresponse()
  File "/usr/local/lib/python3.9/http/client.py", line 1377, in getresponse
    response.begin()
  File "/usr/local/lib/python3.9/http/client.py", line 320, in begin
    version, status, reason = self._read_status()
  File "/usr/local/lib/python3.9/http/client.py", line 289, in _read_status
    raise RemoteDisconnected("Remote end closed connection without"
telegram.vendor.ptb_urllib3.urllib3.exceptions.ProtocolError: ('Connection aborted.', RemoteDisconnected('Remote end closed connection without response'))

The above exception was the direct cause of the following exception:

Traceback (most recent call last):
  File "/home/ftuser/.local/lib/python3.9/site-packages/telegram/ext/updater.py", line 646, in _network_loop_retry
    if not action_cb():
  File "/home/ftuser/.local/lib/python3.9/site-packages/telegram/ext/updater.py", line 597, in polling_action_cb
    updates = self.bot.get_updates(
  File "/home/ftuser/.local/lib/python3.9/site-packages/telegram/ext/extbot.py", line 224, in get_updates
    updates = super().get_updates(
  File "/home/ftuser/.local/lib/python3.9/site-packages/telegram/bot.py", line 130, in decorator
    result = func(*args, **kwargs)
  File "/home/ftuser/.local/lib/python3.9/site-packages/telegram/bot.py", line 3054, in get_updates
    self._post(
  File "/home/ftuser/.local/lib/python3.9/site-packages/telegram/bot.py", line 295, in _post
    return self.request.post(
  File "/home/ftuser/.local/lib/python3.9/site-packages/telegram/utils/request.py", line 361, in post
    result = self._request_wrapper(
  File "/home/ftuser/.local/lib/python3.9/site-packages/telegram/utils/request.py", line 265, in _request_wrapper
    raise NetworkError(f'urllib3 HTTPError {error}') from error
telegram.error.NetworkError: urllib3 HTTPError ('Connection aborted.', RemoteDisconnected('Remote end closed connection without response'))
2022-03-28 15:48:31,644 - freqtrade.worker - INFO - Bot heartbeat. PID=1, version='2022.1', state='STOPPED'
2022-03-28 15:48:38,297 - uvicorn.access - INFO - 172.20.0.1:58316 - "GET /api/v1/ping HTTP/1.1" 200
2022-03-28 15:48:38,311 - uvicorn.access - INFO - 172.20.0.1:58318 - "GET /api/v1/locks HTTP/1.1" 401
2022-03-28 15:48:38,321 - uvicorn.access - INFO - 172.20.0.1:58322 - "GET /api/v1/show_config HTTP/1.1" 401
2022-03-28 15:48:38,330 - uvicorn.access - INFO - 172.20.0.1:58320 - "GET /api/v1/status HTTP/1.1" 401
2022-03-28 15:48:38,366 - uvicorn.access - INFO - 172.20.0.1:58322 - "POST /api/v1/token/refresh HTTP/1.1" 401
2022-03-28 15:48:38,379 - uvicorn.access - INFO - 172.20.0.1:58320 - "POST /api/v1/token/refresh HTTP/1.1" 401
2022-03-28 15:48:38,389 - uvicorn.access - INFO - 172.20.0.1:58318 - "POST /api/v1/token/refresh HTTP/1.1" 401
2022-03-28 15:48:54,902 - telegram.ext.updater - ERROR - Error while getting Updates: urllib3 HTTPError ('Connection aborted.', RemoteDisconnected('Remote end closed connection without response'))
2022-03-28 15:48:54,945 - telegram.ext.dispatcher - ERROR - No error handlers are registered, logging exception.
Traceback (most recent call last):
  File "/home/ftuser/.local/lib/python3.9/site-packages/telegram/vendor/ptb_urllib3/urllib3/connectionpool.py", line 614, in urlopen
    httplib_response = self._make_request(conn, method, url,
  File "/home/ftuser/.local/lib/python3.9/site-packages/telegram/vendor/ptb_urllib3/urllib3/connectionpool.py", line 402, in _make_request
    six.raise_from(e, None)
  File "<string>", line 2, in raise_from
  File "/home/ftuser/.local/lib/python3.9/site-packages/telegram/vendor/ptb_urllib3/urllib3/connectionpool.py", line 398, in _make_request
    httplib_response = conn.getresponse()
  File "/usr/local/lib/python3.9/http/client.py", line 1377, in getresponse
    response.begin()
  File "/usr/local/lib/python3.9/http/client.py", line 320, in begin
    version, status, reason = self._read_status()
  File "/usr/local/lib/python3.9/http/client.py", line 289, in _read_status
    raise RemoteDisconnected("Remote end closed connection without"
http.client.RemoteDisconnected: Remote end closed connection without response

During handling of the above exception, another exception occurred:

Traceback (most recent call last):
  File "/home/ftuser/.local/lib/python3.9/site-packages/telegram/utils/request.py", line 259, in _request_wrapper
    resp = self._con_pool.request(*args, **kwargs)
  File "/home/ftuser/.local/lib/python3.9/site-packages/telegram/vendor/ptb_urllib3/urllib3/request.py", line 68, in request
    return self.request_encode_body(method, url, fields=fields,
  File "/home/ftuser/.local/lib/python3.9/site-packages/telegram/vendor/ptb_urllib3/urllib3/request.py", line 148, in request_encode_body
    return self.urlopen(method, url, **extra_kw)
  File "/home/ftuser/.local/lib/python3.9/site-packages/telegram/vendor/ptb_urllib3/urllib3/poolmanager.py", line 244, in urlopen
    response = conn.urlopen(method, u.request_uri, **kw)
  File "/home/ftuser/.local/lib/python3.9/site-packages/telegram/vendor/ptb_urllib3/urllib3/connectionpool.py", line 665, in urlopen
    retries = retries.increment(method, url, error=e, _pool=self,
  File "/home/ftuser/.local/lib/python3.9/site-packages/telegram/vendor/ptb_urllib3/urllib3/util/retry.py", line 347, in increment
    raise six.reraise(type(error), error, _stacktrace)
  File "/home/ftuser/.local/lib/python3.9/site-packages/telegram/vendor/ptb_urllib3/urllib3/packages/six.py", line 685, in reraise
    raise value.with_traceback(tb)
  File "/home/ftuser/.local/lib/python3.9/site-packages/telegram/vendor/ptb_urllib3/urllib3/connectionpool.py", line 614, in urlopen
    httplib_response = self._make_request(conn, method, url,
  File "/home/ftuser/.local/lib/python3.9/site-packages/telegram/vendor/ptb_urllib3/urllib3/connectionpool.py", line 402, in _make_request
    six.raise_from(e, None)
  File "<string>", line 2, in raise_from
  File "/home/ftuser/.local/lib/python3.9/site-packages/telegram/vendor/ptb_urllib3/urllib3/connectionpool.py", line 398, in _make_request
    httplib_response = conn.getresponse()
  File "/usr/local/lib/python3.9/http/client.py", line 1377, in getresponse
    response.begin()
  File "/usr/local/lib/python3.9/http/client.py", line 320, in begin
    version, status, reason = self._read_status()
  File "/usr/local/lib/python3.9/http/client.py", line 289, in _read_status
    raise RemoteDisconnected("Remote end closed connection without"
telegram.vendor.ptb_urllib3.urllib3.exceptions.ProtocolError: ('Connection aborted.', RemoteDisconnected('Remote end closed connection without response'))

The above exception was the direct cause of the following exception:

Traceback (most recent call last):
  File "/home/ftuser/.local/lib/python3.9/site-packages/telegram/ext/updater.py", line 646, in _network_loop_retry
    if not action_cb():
  File "/home/ftuser/.local/lib/python3.9/site-packages/telegram/ext/updater.py", line 597, in polling_action_cb
    updates = self.bot.get_updates(
  File "/home/ftuser/.local/lib/python3.9/site-packages/telegram/ext/extbot.py", line 224, in get_updates
    updates = super().get_updates(
  File "/home/ftuser/.local/lib/python3.9/site-packages/telegram/bot.py", line 130, in decorator
    result = func(*args, **kwargs)
  File "/home/ftuser/.local/lib/python3.9/site-packages/telegram/bot.py", line 3054, in get_updates
    self._post(
  File "/home/ftuser/.local/lib/python3.9/site-packages/telegram/bot.py", line 295, in _post
    return self.request.post(
  File "/home/ftuser/.local/lib/python3.9/site-packages/telegram/utils/request.py", line 361, in post
    result = self._request_wrapper(
  File "/home/ftuser/.local/lib/python3.9/site-packages/telegram/utils/request.py", line 265, in _request_wrapper
    raise NetworkError(f'urllib3 HTTPError {error}') from error
telegram.error.NetworkError: urllib3 HTTPError ('Connection aborted.', RemoteDisconnected('Remote end closed connection without response'))
2022-03-28 16:27:34,631 - freqtrade.worker - INFO - Bot heartbeat. PID=1, version='2022.1', state='STOPPED'
2022-03-28 16:59:35,198 - freqtrade.worker - INFO - Bot heartbeat. PID=1, version='2022.1', state='STOPPED'
2022-03-28 16:59:40,950 - telegram.ext.updater - ERROR - Error while getting Updates: urllib3 HTTPError ('Connection aborted.', RemoteDisconnected('Remote end closed connection without response'))
2022-03-28 16:59:40,968 - telegram.ext.dispatcher - ERROR - No error handlers are registered, logging exception.
Traceback (most recent call last):
  File "/home/ftuser/.local/lib/python3.9/site-packages/telegram/vendor/ptb_urllib3/urllib3/connectionpool.py", line 614, in urlopen
    httplib_response = self._make_request(conn, method, url,
  File "/home/ftuser/.local/lib/python3.9/site-packages/telegram/vendor/ptb_urllib3/urllib3/connectionpool.py", line 402, in _make_request
    six.raise_from(e, None)
  File "<string>", line 2, in raise_from
  File "/home/ftuser/.local/lib/python3.9/site-packages/telegram/vendor/ptb_urllib3/urllib3/connectionpool.py", line 398, in _make_request
    httplib_response = conn.getresponse()
  File "/usr/local/lib/python3.9/http/client.py", line 1377, in getresponse
    response.begin()
  File "/usr/local/lib/python3.9/http/client.py", line 320, in begin
    version, status, reason = self._read_status()
  File "/usr/local/lib/python3.9/http/client.py", line 289, in _read_status
    raise RemoteDisconnected("Remote end closed connection without"
http.client.RemoteDisconnected: Remote end closed connection without response

During handling of the above exception, another exception occurred:

Traceback (most recent call last):
  File "/home/ftuser/.local/lib/python3.9/site-packages/telegram/utils/request.py", line 259, in _request_wrapper
    resp = self._con_pool.request(*args, **kwargs)
  File "/home/ftuser/.local/lib/python3.9/site-packages/telegram/vendor/ptb_urllib3/urllib3/request.py", line 68, in request
    return self.request_encode_body(method, url, fields=fields,
  File "/home/ftuser/.local/lib/python3.9/site-packages/telegram/vendor/ptb_urllib3/urllib3/request.py", line 148, in request_encode_body
    return self.urlopen(method, url, **extra_kw)
  File "/home/ftuser/.local/lib/python3.9/site-packages/telegram/vendor/ptb_urllib3/urllib3/poolmanager.py", line 244, in urlopen
    response = conn.urlopen(method, u.request_uri, **kw)
  File "/home/ftuser/.local/lib/python3.9/site-packages/telegram/vendor/ptb_urllib3/urllib3/connectionpool.py", line 665, in urlopen
    retries = retries.increment(method, url, error=e, _pool=self,
  File "/home/ftuser/.local/lib/python3.9/site-packages/telegram/vendor/ptb_urllib3/urllib3/util/retry.py", line 347, in increment
    raise six.reraise(type(error), error, _stacktrace)
  File "/home/ftuser/.local/lib/python3.9/site-packages/telegram/vendor/ptb_urllib3/urllib3/packages/six.py", line 685, in reraise
    raise value.with_traceback(tb)
  File "/home/ftuser/.local/lib/python3.9/site-packages/telegram/vendor/ptb_urllib3/urllib3/connectionpool.py", line 614, in urlopen
    httplib_response = self._make_request(conn, method, url,
  File "/home/ftuser/.local/lib/python3.9/site-packages/telegram/vendor/ptb_urllib3/urllib3/connectionpool.py", line 402, in _make_request
    six.raise_from(e, None)
  File "<string>", line 2, in raise_from
  File "/home/ftuser/.local/lib/python3.9/site-packages/telegram/vendor/ptb_urllib3/urllib3/connectionpool.py", line 398, in _make_request
    httplib_response = conn.getresponse()
  File "/usr/local/lib/python3.9/http/client.py", line 1377, in getresponse
    response.begin()
  File "/usr/local/lib/python3.9/http/client.py", line 320, in begin
    version, status, reason = self._read_status()
  File "/usr/local/lib/python3.9/http/client.py", line 289, in _read_status
    raise RemoteDisconnected("Remote end closed connection without"
telegram.vendor.ptb_urllib3.urllib3.exceptions.ProtocolError: ('Connection aborted.', RemoteDisconnected('Remote end closed connection without response'))

The above exception was the direct cause of the following exception:

Traceback (most recent call last):
  File "/home/ftuser/.local/lib/python3.9/site-packages/telegram/ext/updater.py", line 646, in _network_loop_retry
    if not action_cb():
  File "/home/ftuser/.local/lib/python3.9/site-packages/telegram/ext/updater.py", line 597, in polling_action_cb
    updates = self.bot.get_updates(
  File "/home/ftuser/.local/lib/python3.9/site-packages/telegram/ext/extbot.py", line 224, in get_updates
    updates = super().get_updates(
  File "/home/ftuser/.local/lib/python3.9/site-packages/telegram/bot.py", line 130, in decorator
    result = func(*args, **kwargs)
  File "/home/ftuser/.local/lib/python3.9/site-packages/telegram/bot.py", line 3054, in get_updates
    self._post(
  File "/home/ftuser/.local/lib/python3.9/site-packages/telegram/bot.py", line 295, in _post
    return self.request.post(
  File "/home/ftuser/.local/lib/python3.9/site-packages/telegram/utils/request.py", line 361, in post
    result = self._request_wrapper(
  File "/home/ftuser/.local/lib/python3.9/site-packages/telegram/utils/request.py", line 265, in _request_wrapper
    raise NetworkError(f'urllib3 HTTPError {error}') from error
telegram.error.NetworkError: urllib3 HTTPError ('Connection aborted.', RemoteDisconnected('Remote end closed connection without response'))
2022-03-28 16:59:41,450 - uvicorn.access - INFO - 172.20.0.1:58328 - "GET /api/v1/status HTTP/1.1" 401
2022-03-28 16:59:41,474 - uvicorn.access - INFO - 172.20.0.1:58330 - "GET /api/v1/locks HTTP/1.1" 401
2022-03-28 16:59:41,484 - uvicorn.access - INFO - 172.20.0.1:58332 - "GET /api/v1/show_config HTTP/1.1" 401
2022-03-28 16:59:41,496 - uvicorn.access - INFO - 172.20.0.1:58334 - "GET /api/v1/ping HTTP/1.1" 200
2022-03-28 16:59:41,516 - uvicorn.access - INFO - 172.20.0.1:58334 - "POST /api/v1/token/refresh HTTP/1.1" 401
2022-03-28 16:59:41,676 - uvicorn.access - INFO - 172.20.0.1:58334 - "POST /api/v1/token/refresh HTTP/1.1" 401
2022-03-28 16:59:41,721 - uvicorn.access - INFO - 172.20.0.1:58332 - "POST /api/v1/token/refresh HTTP/1.1" 401
2022-03-28 17:47:08,171 - freqtrade.worker - INFO - Bot heartbeat. PID=1, version='2022.1', state='STOPPED'
2022-03-28 18:15:33,184 - freqtrade.worker - INFO - Bot heartbeat. PID=1, version='2022.1', state='STOPPED'
2022-03-28 18:15:39,415 - uvicorn.access - INFO - 172.20.0.1:58344 - "GET /api/v1/ping HTTP/1.1" 200
2022-03-28 18:15:39,462 - uvicorn.access - INFO - 172.20.0.1:58342 - "GET /api/v1/locks HTTP/1.1" 401
2022-03-28 18:15:39,480 - uvicorn.access - INFO - 172.20.0.1:58340 - "GET /api/v1/show_config HTTP/1.1" 401
2022-03-28 18:15:39,493 - uvicorn.access - INFO - 172.20.0.1:58338 - "GET /api/v1/status HTTP/1.1" 401
2022-03-28 18:15:39,554 - uvicorn.access - INFO - 172.20.0.1:58338 - "POST /api/v1/token/refresh HTTP/1.1" 401
2022-03-28 18:15:39,589 - uvicorn.access - INFO - 172.20.0.1:58340 - "POST /api/v1/token/refresh HTTP/1.1" 401
2022-03-28 18:15:39,606 - uvicorn.access - INFO - 172.20.0.1:58342 - "POST /api/v1/token/refresh HTTP/1.1" 401
2022-03-28 18:16:33,322 - freqtrade.worker - INFO - Bot heartbeat. PID=1, version='2022.1', state='STOPPED'
2022-03-28 18:16:38,785 - uvicorn.access - INFO - 172.20.0.1:58348 - "GET /api/v1/status HTTP/1.1" 401
2022-03-28 18:16:38,798 - uvicorn.access - INFO - 172.20.0.1:58350 - "GET /api/v1/show_config HTTP/1.1" 401
2022-03-28 18:16:38,808 - uvicorn.access - INFO - 172.20.0.1:58354 - "GET /api/v1/ping HTTP/1.1" 200
2022-03-28 18:16:38,815 - uvicorn.access - INFO - 172.20.0.1:58352 - "GET /api/v1/locks HTTP/1.1" 401
2022-03-28 18:16:38,831 - uvicorn.access - INFO - 172.20.0.1:58354 - "POST /api/v1/token/refresh HTTP/1.1" 401
2022-03-28 18:16:38,836 - uvicorn.access - INFO - 172.20.0.1:58348 - "POST /api/v1/token/refresh HTTP/1.1" 401
2022-03-28 18:16:38,846 - uvicorn.access - INFO - 172.20.0.1:58352 - "POST /api/v1/token/refresh HTTP/1.1" 401
2022-03-28 18:17:33,423 - freqtrade.worker - INFO - Bot heartbeat. PID=1, version='2022.1', state='STOPPED'
2022-03-28 18:17:38,775 - uvicorn.access - INFO - 172.20.0.1:58356 - "GET /api/v1/status HTTP/1.1" 401
2022-03-28 18:17:38,797 - uvicorn.access - INFO - 172.20.0.1:58358 - "GET /api/v1/show_config HTTP/1.1" 401
2022-03-28 18:17:38,810 - uvicorn.access - INFO - 172.20.0.1:58360 - "GET /api/v1/locks HTTP/1.1" 401
2022-03-28 18:17:38,819 - uvicorn.access - INFO - 172.20.0.1:58362 - "GET /api/v1/ping HTTP/1.1" 200
2022-03-28 18:17:38,857 - uvicorn.access - INFO - 172.20.0.1:58362 - "POST /api/v1/token/refresh HTTP/1.1" 401
2022-03-28 18:17:38,867 - uvicorn.access - INFO - 172.20.0.1:58360 - "POST /api/v1/token/refresh HTTP/1.1" 401
2022-03-28 18:17:38,873 - uvicorn.access - INFO - 172.20.0.1:58358 - "POST /api/v1/token/refresh HTTP/1.1" 401
2022-03-28 18:18:33,526 - freqtrade.worker - INFO - Bot heartbeat. PID=1, version='2022.1', state='STOPPED'
2022-03-28 18:18:38,903 - uvicorn.access - INFO - 172.20.0.1:58364 - "GET /api/v1/ping HTTP/1.1" 200
2022-03-28 18:18:38,920 - uvicorn.access - INFO - 172.20.0.1:58370 - "GET /api/v1/locks HTTP/1.1" 401
2022-03-28 18:18:38,933 - uvicorn.access - INFO - 172.20.0.1:58366 - "GET /api/v1/show_config HTTP/1.1" 401
2022-03-28 18:18:38,942 - uvicorn.access - INFO - 172.20.0.1:58372 - "GET /api/v1/status HTTP/1.1" 401
2022-03-28 18:18:38,982 - uvicorn.access - INFO - 172.20.0.1:58370 - "POST /api/v1/token/refresh HTTP/1.1" 401
2022-03-28 18:18:38,994 - uvicorn.access - INFO - 172.20.0.1:58366 - "POST /api/v1/token/refresh HTTP/1.1" 401
2022-03-28 18:18:39,002 - uvicorn.access - INFO - 172.20.0.1:58372 - "POST /api/v1/token/refresh HTTP/1.1" 401
2022-03-28 18:19:33,648 - freqtrade.worker - INFO - Bot heartbeat. PID=1, version='2022.1', state='STOPPED'
2022-03-28 18:19:38,886 - uvicorn.access - INFO - 172.20.0.1:58374 - "GET /api/v1/show_config HTTP/1.1" 401
2022-03-28 18:19:38,906 - uvicorn.access - INFO - 172.20.0.1:58378 - "GET /api/v1/status HTTP/1.1" 401
2022-03-28 18:19:38,918 - uvicorn.access - INFO - 172.20.0.1:58376 - "GET /api/v1/locks HTTP/1.1" 401
2022-03-28 18:19:38,938 - uvicorn.access - INFO - 172.20.0.1:58380 - "GET /api/v1/ping HTTP/1.1" 200
2022-03-28 18:19:39,026 - uvicorn.access - INFO - 172.20.0.1:58376 - "POST /api/v1/token/refresh HTTP/1.1" 401
2022-03-28 18:19:39,037 - uvicorn.access - INFO - 172.20.0.1:58380 - "POST /api/v1/token/refresh HTTP/1.1" 401
2022-03-28 18:19:39,039 - uvicorn.access - INFO - 172.20.0.1:58378 - "POST /api/v1/token/refresh HTTP/1.1" 401
2022-03-28 18:20:33,861 - freqtrade.worker - INFO - Bot heartbeat. PID=1, version='2022.1', state='STOPPED'
2022-03-28 18:20:38,867 - uvicorn.access - INFO - 172.20.0.1:58384 - "GET /api/v1/status HTTP/1.1" 401
2022-03-28 18:20:38,890 - uvicorn.access - INFO - 172.20.0.1:58382 - "GET /api/v1/show_config HTTP/1.1" 401
2022-03-28 18:20:38,902 - uvicorn.access - INFO - 172.20.0.1:58386 - "GET /api/v1/locks HTTP/1.1" 401
2022-03-28 18:20:38,922 - uvicorn.access - INFO - 172.20.0.1:58388 - "GET /api/v1/ping HTTP/1.1" 200
2022-03-28 18:20:38,996 - uvicorn.access - INFO - 172.20.0.1:58388 - "POST /api/v1/token/refresh HTTP/1.1" 401
2022-03-28 18:20:39,006 - uvicorn.access - INFO - 172.20.0.1:58382 - "POST /api/v1/token/refresh HTTP/1.1" 401
2022-03-28 18:20:39,012 - uvicorn.access - INFO - 172.20.0.1:58386 - "POST /api/v1/token/refresh HTTP/1.1" 401
2022-03-28 18:21:33,977 - freqtrade.worker - INFO - Bot heartbeat. PID=1, version='2022.1', state='STOPPED'
2022-03-28 18:21:38,967 - uvicorn.access - INFO - 172.20.0.1:58390 - "GET /api/v1/status HTTP/1.1" 401
2022-03-28 18:21:38,993 - uvicorn.access - INFO - 172.20.0.1:58392 - "GET /api/v1/show_config HTTP/1.1" 401
2022-03-28 18:21:39,005 - uvicorn.access - INFO - 172.20.0.1:58394 - "GET /api/v1/locks HTTP/1.1" 401
2022-03-28 18:21:39,019 - uvicorn.access - INFO - 172.20.0.1:58396 - "GET /api/v1/ping HTTP/1.1" 200
2022-03-28 18:21:39,062 - uvicorn.access - INFO - 172.20.0.1:58396 - "POST /api/v1/token/refresh HTTP/1.1" 401
2022-03-28 18:21:39,070 - uvicorn.access - INFO - 172.20.0.1:58394 - "POST /api/v1/token/refresh HTTP/1.1" 401
2022-03-28 18:21:39,078 - uvicorn.access - INFO - 172.20.0.1:58392 - "POST /api/v1/token/refresh HTTP/1.1" 401
2022-03-28 18:22:34,103 - freqtrade.worker - INFO - Bot heartbeat. PID=1, version='2022.1', state='STOPPED'
2022-03-28 18:22:38,967 - uvicorn.access - INFO - 172.20.0.1:58398 - "GET /api/v1/status HTTP/1.1" 401
2022-03-28 18:22:38,980 - uvicorn.access - INFO - 172.20.0.1:58402 - "GET /api/v1/locks HTTP/1.1" 401
2022-03-28 18:22:38,992 - uvicorn.access - INFO - 172.20.0.1:58400 - "GET /api/v1/show_config HTTP/1.1" 401
2022-03-28 18:22:39,008 - uvicorn.access - INFO - 172.20.0.1:58404 - "GET /api/v1/ping HTTP/1.1" 200
2022-03-28 18:22:39,026 - uvicorn.access - INFO - 172.20.0.1:58400 - "POST /api/v1/token/refresh HTTP/1.1" 401
2022-03-28 18:22:39,042 - uvicorn.access - INFO - 172.20.0.1:58402 - "POST /api/v1/token/refresh HTTP/1.1" 401
2022-03-28 18:22:39,051 - uvicorn.access - INFO - 172.20.0.1:58404 - "POST /api/v1/token/refresh HTTP/1.1" 401
2022-03-28 18:23:34,229 - freqtrade.worker - INFO - Bot heartbeat. PID=1, version='2022.1', state='STOPPED'
2022-03-28 18:23:39,050 - uvicorn.access - INFO - 172.20.0.1:58410 - "GET /api/v1/status HTTP/1.1" 401
2022-03-28 18:23:39,056 - uvicorn.access - INFO - 172.20.0.1:58406 - "GET /api/v1/show_config HTTP/1.1" 401
2022-03-28 18:23:39,068 - uvicorn.access - INFO - 172.20.0.1:58408 - "GET /api/v1/locks HTTP/1.1" 401
2022-03-28 18:23:39,078 - uvicorn.access - INFO - 172.20.0.1:58412 - "GET /api/v1/ping HTTP/1.1" 200
2022-03-28 18:23:39,095 - uvicorn.access - INFO - 172.20.0.1:58410 - "POST /api/v1/token/refresh HTTP/1.1" 401
2022-03-28 18:23:39,106 - uvicorn.access - INFO - 172.20.0.1:58408 - "POST /api/v1/token/refresh HTTP/1.1" 401
2022-03-28 18:23:39,116 - uvicorn.access - INFO - 172.20.0.1:58406 - "POST /api/v1/token/refresh HTTP/1.1" 401
2022-03-28 18:24:34,363 - freqtrade.worker - INFO - Bot heartbeat. PID=1, version='2022.1', state='STOPPED'
2022-03-28 18:24:39,045 - uvicorn.access - INFO - 172.20.0.1:58414 - "GET /api/v1/status HTTP/1.1" 401
2022-03-28 18:24:39,115 - uvicorn.access - INFO - 172.20.0.1:58414 - "GET /api/v1/show_config HTTP/1.1" 401
2022-03-28 18:24:39,200 - uvicorn.access - INFO - 172.20.0.1:58416 - "GET /api/v1/locks HTTP/1.1" 401
2022-03-28 18:24:39,218 - uvicorn.access - INFO - 172.20.0.1:58418 - "GET /api/v1/ping HTTP/1.1" 200
2022-03-28 18:24:39,231 - uvicorn.access - INFO - 172.20.0.1:58414 - "POST /api/v1/token/refresh HTTP/1.1" 401
2022-03-28 18:24:39,243 - uvicorn.access - INFO - 172.20.0.1:58420 - "POST /api/v1/token/refresh HTTP/1.1" 401
2022-03-28 18:24:39,266 - uvicorn.access - INFO - 172.20.0.1:58420 - "POST /api/v1/token/refresh HTTP/1.1" 401
2022-03-28 18:25:34,499 - freqtrade.worker - INFO - Bot heartbeat. PID=1, version='2022.1', state='STOPPED'
2022-03-28 18:25:39,021 - uvicorn.access - INFO - 172.20.0.1:58422 - "GET /api/v1/ping HTTP/1.1" 200
2022-03-28 18:25:39,041 - uvicorn.access - INFO - 172.20.0.1:58424 - "GET /api/v1/show_config HTTP/1.1" 401
2022-03-28 18:25:39,046 - uvicorn.access - INFO - 172.20.0.1:58426 - "GET /api/v1/status HTTP/1.1" 401
2022-03-28 18:25:39,054 - uvicorn.access - INFO - 172.20.0.1:58428 - "GET /api/v1/locks HTTP/1.1" 401
2022-03-28 18:25:39,063 - uvicorn.access - INFO - 172.20.0.1:58424 - "POST /api/v1/token/refresh HTTP/1.1" 401
2022-03-28 18:25:39,075 - uvicorn.access - INFO - 172.20.0.1:58426 - "POST /api/v1/token/refresh HTTP/1.1" 401
2022-03-28 18:25:39,081 - uvicorn.access - INFO - 172.20.0.1:58428 - "POST /api/v1/token/refresh HTTP/1.1" 401
2022-03-28 18:26:34,635 - freqtrade.worker - INFO - Bot heartbeat. PID=1, version='2022.1', state='STOPPED'
2022-03-28 18:26:38,913 - uvicorn.access - INFO - 172.20.0.1:58430 - "GET /api/v1/status HTTP/1.1" 401
2022-03-28 18:26:38,929 - uvicorn.access - INFO - 172.20.0.1:58432 - "GET /api/v1/locks HTTP/1.1" 401
2022-03-28 18:26:38,954 - uvicorn.access - INFO - 172.20.0.1:58434 - "GET /api/v1/show_config HTTP/1.1" 401
2022-03-28 18:26:38,973 - uvicorn.access - INFO - 172.20.0.1:58436 - "GET /api/v1/ping HTTP/1.1" 200
2022-03-28 18:26:38,995 - uvicorn.access - INFO - 172.20.0.1:58436 - "POST /api/v1/token/refresh HTTP/1.1" 401
2022-03-28 18:26:39,011 - uvicorn.access - INFO - 172.20.0.1:58434 - "POST /api/v1/token/refresh HTTP/1.1" 401
2022-03-28 18:26:39,022 - uvicorn.access - INFO - 172.20.0.1:58432 - "POST /api/v1/token/refresh HTTP/1.1" 401
2022-03-28 18:27:34,750 - freqtrade.worker - INFO - Bot heartbeat. PID=1, version='2022.1', state='STOPPED'
2022-03-28 18:27:38,892 - uvicorn.access - INFO - 172.20.0.1:58438 - "GET /api/v1/status HTTP/1.1" 401
2022-03-28 18:27:38,910 - uvicorn.access - INFO - 172.20.0.1:58442 - "GET /api/v1/ping HTTP/1.1" 200
2022-03-28 18:27:38,922 - uvicorn.access - INFO - 172.20.0.1:58440 - "GET /api/v1/show_config HTTP/1.1" 401
2022-03-28 18:27:38,932 - uvicorn.access - INFO - 172.20.0.1:58444 - "GET /api/v1/locks HTTP/1.1" 401
2022-03-28 18:27:38,946 - uvicorn.access - INFO - 172.20.0.1:58440 - "POST /api/v1/token/refresh HTTP/1.1" 401
2022-03-28 18:27:38,961 - uvicorn.access - INFO - 172.20.0.1:58444 - "POST /api/v1/token/refresh HTTP/1.1" 401
2022-03-28 18:27:38,976 - uvicorn.access - INFO - 172.20.0.1:58442 - "POST /api/v1/token/refresh HTTP/1.1" 401
2022-03-28 18:28:34,868 - freqtrade.worker - INFO - Bot heartbeat. PID=1, version='2022.1', state='STOPPED'
2022-03-28 18:28:39,041 - uvicorn.access - INFO - 172.20.0.1:58450 - "GET /api/v1/locks HTTP/1.1" 401
2022-03-28 18:28:39,072 - uvicorn.access - INFO - 172.20.0.1:58452 - "GET /api/v1/ping HTTP/1.1" 200
2022-03-28 18:28:39,091 - uvicorn.access - INFO - 172.20.0.1:58448 - "GET /api/v1/status HTTP/1.1" 401
2022-03-28 18:28:39,098 - uvicorn.access - INFO - 172.20.0.1:58446 - "GET /api/v1/show_config HTTP/1.1" 401
2022-03-28 18:28:39,113 - uvicorn.access - INFO - 172.20.0.1:58450 - "POST /api/v1/token/refresh HTTP/1.1" 401
2022-03-28 18:28:39,118 - uvicorn.access - INFO - 172.20.0.1:58448 - "POST /api/v1/token/refresh HTTP/1.1" 401
2022-03-28 18:28:39,123 - uvicorn.access - INFO - 172.20.0.1:58446 - "POST /api/v1/token/refresh HTTP/1.1" 401
2022-03-28 18:29:34,978 - freqtrade.worker - INFO - Bot heartbeat. PID=1, version='2022.1', state='STOPPED'
2022-03-28 18:29:39,021 - uvicorn.access - INFO - 172.20.0.1:58454 - "GET /api/v1/ping HTTP/1.1" 200
2022-03-28 18:29:39,037 - uvicorn.access - INFO - 172.20.0.1:58460 - "GET /api/v1/show_config HTTP/1.1" 401
2022-03-28 18:29:39,049 - uvicorn.access - INFO - 172.20.0.1:58458 - "GET /api/v1/locks HTTP/1.1" 401
2022-03-28 18:29:39,055 - uvicorn.access - INFO - 172.20.0.1:58456 - "GET /api/v1/status HTTP/1.1" 401
2022-03-28 18:29:39,065 - uvicorn.access - INFO - 172.20.0.1:58460 - "POST /api/v1/token/refresh HTTP/1.1" 401
2022-03-28 18:29:39,069 - uvicorn.access - INFO - 172.20.0.1:58458 - "POST /api/v1/token/refresh HTTP/1.1" 401
2022-03-28 18:29:39,073 - uvicorn.access - INFO - 172.20.0.1:58456 - "POST /api/v1/token/refresh HTTP/1.1" 401
2022-03-28 18:30:35,080 - freqtrade.worker - INFO - Bot heartbeat. PID=1, version='2022.1', state='STOPPED'
2022-03-28 18:30:39,158 - uvicorn.access - INFO - 172.20.0.1:58466 - "GET /api/v1/locks HTTP/1.1" 401
2022-03-28 18:30:39,182 - uvicorn.access - INFO - 172.20.0.1:58462 - "GET /api/v1/status HTTP/1.1" 401
2022-03-28 18:30:39,196 - uvicorn.access - INFO - 172.20.0.1:58464 - "GET /api/v1/show_config HTTP/1.1" 401
2022-03-28 18:30:39,225 - uvicorn.access - INFO - 172.20.0.1:58468 - "GET /api/v1/ping HTTP/1.1" 200
2022-03-28 18:30:39,240 - uvicorn.access - INFO - 172.20.0.1:58462 - "POST /api/v1/token/refresh HTTP/1.1" 401
2022-03-28 18:30:39,250 - uvicorn.access - INFO - 172.20.0.1:58466 - "POST /api/v1/token/refresh HTTP/1.1" 401
2022-03-28 18:30:39,258 - uvicorn.access - INFO - 172.20.0.1:58464 - "POST /api/v1/token/refresh HTTP/1.1" 401
2022-03-28 18:31:35,188 - freqtrade.worker - INFO - Bot heartbeat. PID=1, version='2022.1', state='STOPPED'
2022-03-28 18:31:39,206 - uvicorn.access - INFO - 172.20.0.1:58472 - "GET /api/v1/show_config HTTP/1.1" 401
2022-03-28 18:31:39,238 - uvicorn.access - INFO - 172.20.0.1:58470 - "GET /api/v1/locks HTTP/1.1" 401
2022-03-28 18:31:39,244 - uvicorn.access - INFO - 172.20.0.1:58476 - "GET /api/v1/status HTTP/1.1" 401
2022-03-28 18:31:39,257 - uvicorn.access - INFO - 172.20.0.1:58474 - "GET /api/v1/ping HTTP/1.1" 200
2022-03-28 18:31:39,576 - uvicorn.access - INFO - 172.20.0.1:58474 - "POST /api/v1/token/refresh HTTP/1.1" 401
2022-03-28 18:31:39,588 - uvicorn.access - INFO - 172.20.0.1:58476 - "POST /api/v1/token/refresh HTTP/1.1" 401
2022-03-28 18:31:39,593 - uvicorn.access - INFO - 172.20.0.1:58470 - "POST /api/v1/token/refresh HTTP/1.1" 401
2022-03-28 18:32:35,321 - freqtrade.worker - INFO - Bot heartbeat. PID=1, version='2022.1', state='STOPPED'
2022-03-28 18:32:38,937 - uvicorn.access - INFO - 172.20.0.1:58478 - "GET /api/v1/status HTTP/1.1" 401
2022-03-28 18:32:38,964 - uvicorn.access - INFO - 172.20.0.1:58482 - "GET /api/v1/show_config HTTP/1.1" 401
2022-03-28 18:32:38,979 - uvicorn.access - INFO - 172.20.0.1:58480 - "GET /api/v1/locks HTTP/1.1" 401
2022-03-28 18:32:38,993 - uvicorn.access - INFO - 172.20.0.1:58484 - "GET /api/v1/ping HTTP/1.1" 200
2022-03-28 18:32:39,011 - uvicorn.access - INFO - 172.20.0.1:58480 - "POST /api/v1/token/refresh HTTP/1.1" 401
2022-03-28 18:32:39,036 - uvicorn.access - INFO - 172.20.0.1:58482 - "POST /api/v1/token/refresh HTTP/1.1" 401
2022-03-28 18:32:39,046 - uvicorn.access - INFO - 172.20.0.1:58478 - "POST /api/v1/token/refresh HTTP/1.1" 401
2022-03-28 18:33:35,444 - freqtrade.worker - INFO - Bot heartbeat. PID=1, version='2022.1', state='STOPPED'
2022-03-28 18:33:38,836 - uvicorn.access - INFO - 172.20.0.1:58486 - "GET /api/v1/status HTTP/1.1" 401
2022-03-28 18:33:38,859 - uvicorn.access - INFO - 172.20.0.1:58490 - "GET /api/v1/locks HTTP/1.1" 401
2022-03-28 18:33:38,869 - uvicorn.access - INFO - 172.20.0.1:58488 - "GET /api/v1/show_config HTTP/1.1" 401
2022-03-28 18:33:38,877 - uvicorn.access - INFO - 172.20.0.1:58492 - "GET /api/v1/ping HTTP/1.1" 200
2022-03-28 18:33:38,884 - uvicorn.access - INFO - 172.20.0.1:58488 - "POST /api/v1/token/refresh HTTP/1.1" 401
2022-03-28 18:33:38,888 - uvicorn.access - INFO - 172.20.0.1:58490 - "POST /api/v1/token/refresh HTTP/1.1" 401
2022-03-28 18:33:38,895 - uvicorn.access - INFO - 172.20.0.1:58486 - "POST /api/v1/token/refresh HTTP/1.1" 401
2022-03-28 18:34:35,567 - freqtrade.worker - INFO - Bot heartbeat. PID=1, version='2022.1', state='STOPPED'
2022-03-28 18:34:38,888 - uvicorn.access - INFO - 172.20.0.1:58494 - "GET /api/v1/show_config HTTP/1.1" 401
2022-03-28 18:34:38,904 - uvicorn.access - INFO - 172.20.0.1:58500 - "GET /api/v1/ping HTTP/1.1" 200
2022-03-28 18:34:38,916 - uvicorn.access - INFO - 172.20.0.1:58502 - "GET /api/v1/locks HTTP/1.1" 401
2022-03-28 18:34:38,928 - uvicorn.access - INFO - 172.20.0.1:58496 - "GET /api/v1/status HTTP/1.1" 401
2022-03-28 18:34:38,941 - uvicorn.access - INFO - 172.20.0.1:58500 - "POST /api/v1/token/refresh HTTP/1.1" 401
2022-03-28 18:34:38,955 - uvicorn.access - INFO - 172.20.0.1:58496 - "POST /api/v1/token/refresh HTTP/1.1" 401
2022-03-28 18:34:38,968 - uvicorn.access - INFO - 172.20.0.1:58500 - "POST /api/v1/token/refresh HTTP/1.1" 401
2022-03-28 18:35:35,735 - freqtrade.worker - INFO - Bot heartbeat. PID=1, version='2022.1', state='STOPPED'
2022-03-28 18:35:39,045 - uvicorn.access - INFO - 172.20.0.1:58508 - "GET /api/v1/locks HTTP/1.1" 401
2022-03-28 18:35:39,063 - uvicorn.access - INFO - 172.20.0.1:58504 - "GET /api/v1/status HTTP/1.1" 401
2022-03-28 18:35:39,080 - uvicorn.access - INFO - 172.20.0.1:58506 - "GET /api/v1/show_config HTTP/1.1" 401
2022-03-28 18:35:39,096 - uvicorn.access - INFO - 172.20.0.1:58510 - "GET /api/v1/ping HTTP/1.1" 200
2022-03-28 18:35:39,119 - uvicorn.access - INFO - 172.20.0.1:58506 - "POST /api/v1/token/refresh HTTP/1.1" 401
2022-03-28 18:35:39,133 - uvicorn.access - INFO - 172.20.0.1:58504 - "POST /api/v1/token/refresh HTTP/1.1" 401
2022-03-28 18:35:39,139 - uvicorn.access - INFO - 172.20.0.1:58510 - "POST /api/v1/token/refresh HTTP/1.1" 401
2022-03-28 18:36:35,862 - freqtrade.worker - INFO - Bot heartbeat. PID=1, version='2022.1', state='STOPPED'
2022-03-28 18:36:38,898 - uvicorn.access - INFO - 172.20.0.1:58512 - "GET /api/v1/status HTTP/1.1" 401
2022-03-28 18:36:38,912 - uvicorn.access - INFO - 172.20.0.1:58516 - "GET /api/v1/locks HTTP/1.1" 401
2022-03-28 18:36:38,929 - uvicorn.access - INFO - 172.20.0.1:58514 - "GET /api/v1/show_config HTTP/1.1" 401
2022-03-28 18:36:38,942 - uvicorn.access - INFO - 172.20.0.1:58518 - "GET /api/v1/ping HTTP/1.1" 200
2022-03-28 18:36:39,014 - uvicorn.access - INFO - 172.20.0.1:58518 - "POST /api/v1/token/refresh HTTP/1.1" 401
2022-03-28 18:36:39,023 - uvicorn.access - INFO - 172.20.0.1:58514 - "POST /api/v1/token/refresh HTTP/1.1" 401
2022-03-28 18:36:39,031 - uvicorn.access - INFO - 172.20.0.1:58516 - "POST /api/v1/token/refresh HTTP/1.1" 401
2022-03-28 18:37:35,970 - freqtrade.worker - INFO - Bot heartbeat. PID=1, version='2022.1', state='STOPPED'
2022-03-28 18:37:39,105 - uvicorn.access - INFO - 172.20.0.1:58520 - "GET /api/v1/status HTTP/1.1" 401
2022-03-28 18:37:39,138 - uvicorn.access - INFO - 172.20.0.1:58522 - "GET /api/v1/show_config HTTP/1.1" 401
2022-03-28 18:37:39,163 - uvicorn.access - INFO - 172.20.0.1:58524 - "GET /api/v1/locks HTTP/1.1" 401
2022-03-28 18:37:39,181 - uvicorn.access - INFO - 172.20.0.1:58526 - "GET /api/v1/ping HTTP/1.1" 200
2022-03-28 18:37:39,208 - uvicorn.access - INFO - 172.20.0.1:58522 - "POST /api/v1/token/refresh HTTP/1.1" 401
2022-03-28 18:37:39,222 - uvicorn.access - INFO - 172.20.0.1:58526 - "POST /api/v1/token/refresh HTTP/1.1" 401
2022-03-28 18:37:39,233 - uvicorn.access - INFO - 172.20.0.1:58524 - "POST /api/v1/token/refresh HTTP/1.1" 401
2022-03-28 18:38:36,101 - freqtrade.worker - INFO - Bot heartbeat. PID=1, version='2022.1', state='STOPPED'
2022-03-28 18:38:39,089 - uvicorn.access - INFO - 172.20.0.1:58532 - "GET /api/v1/status HTTP/1.1" 401
2022-03-28 18:38:39,099 - uvicorn.access - INFO - 172.20.0.1:58530 - "GET /api/v1/locks HTTP/1.1" 401
2022-03-28 18:38:39,105 - uvicorn.access - INFO - 172.20.0.1:58528 - "GET /api/v1/show_config HTTP/1.1" 401
2022-03-28 18:38:39,117 - uvicorn.access - INFO - 172.20.0.1:58534 - "GET /api/v1/ping HTTP/1.1" 200
2022-03-28 18:38:39,123 - uvicorn.access - INFO - 172.20.0.1:58530 - "POST /api/v1/token/refresh HTTP/1.1" 401
2022-03-28 18:38:39,132 - uvicorn.access - INFO - 172.20.0.1:58532 - "POST /api/v1/token/refresh HTTP/1.1" 401
2022-03-28 18:38:39,139 - uvicorn.access - INFO - 172.20.0.1:58528 - "POST /api/v1/token/refresh HTTP/1.1" 401
2022-03-28 18:39:36,211 - freqtrade.worker - INFO - Bot heartbeat. PID=1, version='2022.1', state='STOPPED'
2022-03-28 18:39:39,461 - uvicorn.access - INFO - 172.20.0.1:58540 - "GET /api/v1/status HTTP/1.1" 401
2022-03-28 18:39:39,474 - uvicorn.access - INFO - 172.20.0.1:58536 - "GET /api/v1/locks HTTP/1.1" 401
2022-03-28 18:39:39,479 - uvicorn.access - INFO - 172.20.0.1:58538 - "GET /api/v1/show_config HTTP/1.1" 401
2022-03-28 18:39:39,487 - uvicorn.access - INFO - 172.20.0.1:58542 - "GET /api/v1/ping HTTP/1.1" 200
2022-03-28 18:39:39,495 - uvicorn.access - INFO - 172.20.0.1:58538 - "POST /api/v1/token/refresh HTTP/1.1" 401
2022-03-28 18:39:39,501 - uvicorn.access - INFO - 172.20.0.1:58536 - "POST /api/v1/token/refresh HTTP/1.1" 401
2022-03-28 18:39:39,506 - uvicorn.access - INFO - 172.20.0.1:58540 - "POST /api/v1/token/refresh HTTP/1.1" 401
2022-03-28 18:40:36,324 - freqtrade.worker - INFO - Bot heartbeat. PID=1, version='2022.1', state='STOPPED'
2022-03-28 18:40:39,200 - uvicorn.access - INFO - 172.20.0.1:58544 - "GET /api/v1/status HTTP/1.1" 401
2022-03-28 18:40:39,240 - uvicorn.access - INFO - 172.20.0.1:58548 - "GET /api/v1/locks HTTP/1.1" 401
2022-03-28 18:40:39,255 - uvicorn.access - INFO - 172.20.0.1:58546 - "GET /api/v1/ping HTTP/1.1" 200
2022-03-28 18:40:39,269 - uvicorn.access - INFO - 172.20.0.1:58550 - "GET /api/v1/show_config HTTP/1.1" 401
2022-03-28 18:40:39,296 - uvicorn.access - INFO - 172.20.0.1:58550 - "POST /api/v1/token/refresh HTTP/1.1" 401
2022-03-28 18:40:39,307 - uvicorn.access - INFO - 172.20.0.1:58546 - "POST /api/v1/token/refresh HTTP/1.1" 401
2022-03-28 18:40:39,316 - uvicorn.access - INFO - 172.20.0.1:58548 - "POST /api/v1/token/refresh HTTP/1.1" 401
2022-03-28 18:41:36,440 - freqtrade.worker - INFO - Bot heartbeat. PID=1, version='2022.1', state='STOPPED'
2022-03-28 18:41:38,977 - uvicorn.access - INFO - 172.20.0.1:58552 - "GET /api/v1/status HTTP/1.1" 401
2022-03-28 18:41:39,000 - uvicorn.access - INFO - 172.20.0.1:58554 - "GET /api/v1/show_config HTTP/1.1" 401
2022-03-28 18:41:39,020 - uvicorn.access - INFO - 172.20.0.1:58558 - "GET /api/v1/locks HTTP/1.1" 401
2022-03-28 18:41:39,039 - uvicorn.access - INFO - 172.20.0.1:58556 - "GET /api/v1/ping HTTP/1.1" 200
2022-03-28 18:41:39,271 - uvicorn.access - INFO - 172.20.0.1:58556 - "POST /api/v1/token/refresh HTTP/1.1" 401
2022-03-28 18:41:39,290 - uvicorn.access - INFO - 172.20.0.1:58558 - "POST /api/v1/token/refresh HTTP/1.1" 401
2022-03-28 18:41:39,303 - uvicorn.access - INFO - 172.20.0.1:58554 - "POST /api/v1/token/refresh HTTP/1.1" 401
2022-03-28 18:42:36,592 - freqtrade.worker - INFO - Bot heartbeat. PID=1, version='2022.1', state='STOPPED'
2022-03-28 18:42:39,067 - uvicorn.access - INFO - 172.20.0.1:58562 - "GET /api/v1/status HTTP/1.1" 401
2022-03-28 18:42:39,102 - uvicorn.access - INFO - 172.20.0.1:58568 - "GET /api/v1/show_config HTTP/1.1" 401
2022-03-28 18:42:39,113 - uvicorn.access - INFO - 172.20.0.1:58560 - "GET /api/v1/locks HTTP/1.1" 401
2022-03-28 18:42:39,132 - uvicorn.access - INFO - 172.20.0.1:58566 - "GET /api/v1/ping HTTP/1.1" 200
2022-03-28 18:42:39,169 - uvicorn.access - INFO - 172.20.0.1:58566 - "POST /api/v1/token/refresh HTTP/1.1" 401
2022-03-28 18:42:39,187 - uvicorn.access - INFO - 172.20.0.1:58560 - "POST /api/v1/token/refresh HTTP/1.1" 401
2022-03-28 18:42:39,195 - uvicorn.access - INFO - 172.20.0.1:58568 - "POST /api/v1/token/refresh HTTP/1.1" 401
2022-03-28 18:43:36,721 - freqtrade.worker - INFO - Bot heartbeat. PID=1, version='2022.1', state='STOPPED'
2022-03-28 18:43:38,937 - uvicorn.access - INFO - 172.20.0.1:58572 - "GET /api/v1/locks HTTP/1.1" 401
2022-03-28 18:43:38,957 - uvicorn.access - INFO - 172.20.0.1:58570 - "GET /api/v1/status HTTP/1.1" 401
2022-03-28 18:43:38,980 - uvicorn.access - INFO - 172.20.0.1:58578 - "GET /api/v1/ping HTTP/1.1" 200
2022-03-28 18:43:38,995 - uvicorn.access - INFO - 172.20.0.1:58576 - "GET /api/v1/show_config HTTP/1.1" 401
2022-03-28 18:43:39,033 - uvicorn.access - INFO - 172.20.0.1:58576 - "POST /api/v1/token/refresh HTTP/1.1" 401
2022-03-28 18:43:39,041 - uvicorn.access - INFO - 172.20.0.1:58578 - "POST /api/v1/token/refresh HTTP/1.1" 401
2022-03-28 18:43:39,059 - uvicorn.access - INFO - 172.20.0.1:58570 - "POST /api/v1/token/refresh HTTP/1.1" 401
2022-03-28 18:44:36,861 - freqtrade.worker - INFO - Bot heartbeat. PID=1, version='2022.1', state='STOPPED'
2022-03-28 18:44:38,920 - uvicorn.access - INFO - 172.20.0.1:58580 - "GET /api/v1/status HTTP/1.1" 401
2022-03-28 18:44:38,931 - uvicorn.access - INFO - 172.20.0.1:58582 - "GET /api/v1/show_config HTTP/1.1" 401
2022-03-28 18:44:38,946 - uvicorn.access - INFO - 172.20.0.1:58586 - "GET /api/v1/locks HTTP/1.1" 401
2022-03-28 18:44:38,959 - uvicorn.access - INFO - 172.20.0.1:58584 - "GET /api/v1/ping HTTP/1.1" 200
2022-03-28 18:44:39,002 - uvicorn.access - INFO - 172.20.0.1:58582 - "POST /api/v1/token/refresh HTTP/1.1" 401
2022-03-28 18:44:39,013 - uvicorn.access - INFO - 172.20.0.1:58586 - "POST /api/v1/token/refresh HTTP/1.1" 401
2022-03-28 18:44:39,027 - uvicorn.access - INFO - 172.20.0.1:58584 - "POST /api/v1/token/refresh HTTP/1.1" 401
2022-03-28 18:45:37,016 - freqtrade.worker - INFO - Bot heartbeat. PID=1, version='2022.1', state='STOPPED'
2022-03-28 18:45:39,209 - uvicorn.access - INFO - 172.20.0.1:58594 - "GET /api/v1/show_config HTTP/1.1" 401
2022-03-28 18:45:39,220 - uvicorn.access - INFO - 172.20.0.1:58588 - "GET /api/v1/status HTTP/1.1" 401
2022-03-28 18:45:39,233 - uvicorn.access - INFO - 172.20.0.1:58590 - "GET /api/v1/locks HTTP/1.1" 401
2022-03-28 18:45:39,247 - uvicorn.access - INFO - 172.20.0.1:58592 - "GET /api/v1/ping HTTP/1.1" 200
2022-03-28 18:45:39,270 - uvicorn.access - INFO - 172.20.0.1:58590 - "POST /api/v1/token/refresh HTTP/1.1" 401
2022-03-28 18:45:39,289 - uvicorn.access - INFO - 172.20.0.1:58592 - "POST /api/v1/token/refresh HTTP/1.1" 401
2022-03-28 18:45:39,293 - uvicorn.access - INFO - 172.20.0.1:58588 - "POST /api/v1/token/refresh HTTP/1.1" 401
2022-03-28 18:46:37,181 - freqtrade.worker - INFO - Bot heartbeat. PID=1, version='2022.1', state='STOPPED'
2022-03-28 18:46:39,186 - uvicorn.access - INFO - 172.20.0.1:58602 - "GET /api/v1/ping HTTP/1.1" 200
2022-03-28 18:46:39,199 - uvicorn.access - INFO - 172.20.0.1:58598 - "GET /api/v1/locks HTTP/1.1" 401
2022-03-28 18:46:39,205 - uvicorn.access - INFO - 172.20.0.1:58596 - "GET /api/v1/status HTTP/1.1" 401
2022-03-28 18:46:39,208 - uvicorn.access - INFO - 172.20.0.1:58604 - "GET /api/v1/show_config HTTP/1.1" 401
2022-03-28 18:46:39,218 - uvicorn.access - INFO - 172.20.0.1:58596 - "POST /api/v1/token/refresh HTTP/1.1" 401
2022-03-28 18:46:39,224 - uvicorn.access - INFO - 172.20.0.1:58604 - "POST /api/v1/token/refresh HTTP/1.1" 401
2022-03-28 18:46:39,228 - uvicorn.access - INFO - 172.20.0.1:58598 - "POST /api/v1/token/refresh HTTP/1.1" 401
2022-03-28 18:47:37,294 - freqtrade.worker - INFO - Bot heartbeat. PID=1, version='2022.1', state='STOPPED'
2022-03-28 18:47:38,969 - uvicorn.access - INFO - 172.20.0.1:58608 - "GET /api/v1/show_config HTTP/1.1" 401
2022-03-28 18:47:39,001 - uvicorn.access - INFO - 172.20.0.1:58612 - "GET /api/v1/status HTTP/1.1" 401
2022-03-28 18:47:39,026 - uvicorn.access - INFO - 172.20.0.1:58606 - "GET /api/v1/locks HTTP/1.1" 401
2022-03-28 18:47:39,050 - uvicorn.access - INFO - 172.20.0.1:58614 - "GET /api/v1/ping HTTP/1.1" 200
2022-03-28 18:47:39,289 - uvicorn.access - INFO - 172.20.0.1:58614 - "POST /api/v1/token/refresh HTTP/1.1" 401
2022-03-28 18:47:39,317 - uvicorn.access - INFO - 172.20.0.1:58606 - "POST /api/v1/token/refresh HTTP/1.1" 401
2022-03-28 18:47:39,338 - uvicorn.access - INFO - 172.20.0.1:58612 - "POST /api/v1/token/refresh HTTP/1.1" 401
2022-03-28 18:48:37,458 - freqtrade.worker - INFO - Bot heartbeat. PID=1, version='2022.1', state='STOPPED'
2022-03-28 18:48:38,963 - uvicorn.access - INFO - 172.20.0.1:58618 - "GET /api/v1/status HTTP/1.1" 401
2022-03-28 18:48:38,988 - uvicorn.access - INFO - 172.20.0.1:58616 - "GET /api/v1/locks HTTP/1.1" 401
2022-03-28 18:48:39,003 - uvicorn.access - INFO - 172.20.0.1:58620 - "GET /api/v1/show_config HTTP/1.1" 401
2022-03-28 18:48:39,022 - uvicorn.access - INFO - 172.20.0.1:58622 - "GET /api/v1/ping HTTP/1.1" 200
2022-03-28 18:48:39,055 - uvicorn.access - INFO - 172.20.0.1:58620 - "POST /api/v1/token/refresh HTTP/1.1" 401
2022-03-28 18:48:39,065 - uvicorn.access - INFO - 172.20.0.1:58618 - "POST /api/v1/token/refresh HTTP/1.1" 401
2022-03-28 18:48:39,075 - uvicorn.access - INFO - 172.20.0.1:58616 - "POST /api/v1/token/refresh HTTP/1.1" 401
2022-03-28 18:49:37,591 - freqtrade.worker - INFO - Bot heartbeat. PID=1, version='2022.1', state='STOPPED'
2022-03-28 18:49:39,059 - uvicorn.access - INFO - 172.20.0.1:58626 - "GET /api/v1/ping HTTP/1.1" 200
2022-03-28 18:49:39,068 - uvicorn.access - INFO - 172.20.0.1:58630 - "GET /api/v1/status HTTP/1.1" 401
2022-03-28 18:49:39,074 - uvicorn.access - INFO - 172.20.0.1:58624 - "GET /api/v1/show_config HTTP/1.1" 401
2022-03-28 18:49:39,078 - uvicorn.access - INFO - 172.20.0.1:58632 - "GET /api/v1/locks HTTP/1.1" 401
2022-03-28 18:49:39,089 - uvicorn.access - INFO - 172.20.0.1:58624 - "POST /api/v1/token/refresh HTTP/1.1" 401
2022-03-28 18:49:39,093 - uvicorn.access - INFO - 172.20.0.1:58630 - "POST /api/v1/token/refresh HTTP/1.1" 401
2022-03-28 18:49:39,101 - uvicorn.access - INFO - 172.20.0.1:58632 - "POST /api/v1/token/refresh HTTP/1.1" 401
2022-03-28 18:50:37,727 - freqtrade.worker - INFO - Bot heartbeat. PID=1, version='2022.1', state='STOPPED'
2022-03-28 18:50:38,936 - uvicorn.access - INFO - 172.20.0.1:58638 - "GET /api/v1/status HTTP/1.1" 401
2022-03-28 18:50:38,953 - uvicorn.access - INFO - 172.20.0.1:58636 - "GET /api/v1/show_config HTTP/1.1" 401
2022-03-28 18:50:38,971 - uvicorn.access - INFO - 172.20.0.1:58640 - "GET /api/v1/locks HTTP/1.1" 401
2022-03-28 18:50:38,983 - uvicorn.access - INFO - 172.20.0.1:58642 - "GET /api/v1/ping HTTP/1.1" 200
2022-03-28 18:50:39,016 - uvicorn.access - INFO - 172.20.0.1:58640 - "POST /api/v1/token/refresh HTTP/1.1" 401
2022-03-28 18:50:39,021 - uvicorn.access - INFO - 172.20.0.1:58636 - "POST /api/v1/token/refresh HTTP/1.1" 401
2022-03-28 18:50:39,025 - uvicorn.access - INFO - 172.20.0.1:58642 - "POST /api/v1/token/refresh HTTP/1.1" 401
2022-03-28 18:51:37,875 - freqtrade.worker - INFO - Bot heartbeat. PID=1, version='2022.1', state='STOPPED'
2022-03-28 18:51:38,943 - uvicorn.access - INFO - 172.20.0.1:58644 - "GET /api/v1/status HTTP/1.1" 401
2022-03-28 18:51:38,979 - uvicorn.access - INFO - 172.20.0.1:58648 - "GET /api/v1/ping HTTP/1.1" 200
2022-03-28 18:51:38,994 - uvicorn.access - INFO - 172.20.0.1:58646 - "GET /api/v1/show_config HTTP/1.1" 401
2022-03-28 18:51:39,008 - uvicorn.access - INFO - 172.20.0.1:58650 - "GET /api/v1/locks HTTP/1.1" 401
2022-03-28 18:51:39,050 - uvicorn.access - INFO - 172.20.0.1:58650 - "POST /api/v1/token/refresh HTTP/1.1" 401
2022-03-28 18:51:39,064 - uvicorn.access - INFO - 172.20.0.1:58646 - "POST /api/v1/token/refresh HTTP/1.1" 401
2022-03-28 18:51:39,073 - uvicorn.access - INFO - 172.20.0.1:58648 - "POST /api/v1/token/refresh HTTP/1.1" 401
2022-03-28 18:52:38,038 - freqtrade.worker - INFO - Bot heartbeat. PID=1, version='2022.1', state='STOPPED'
2022-03-28 18:52:39,325 - uvicorn.access - INFO - 172.20.0.1:58656 - "GET /api/v1/status HTTP/1.1" 401
2022-03-28 18:52:39,338 - uvicorn.access - INFO - 172.20.0.1:58652 - "GET /api/v1/locks HTTP/1.1" 401
2022-03-28 18:52:39,349 - uvicorn.access - INFO - 172.20.0.1:58654 - "GET /api/v1/show_config HTTP/1.1" 401
2022-03-28 18:52:39,361 - uvicorn.access - INFO - 172.20.0.1:58658 - "GET /api/v1/ping HTTP/1.1" 200
2022-03-28 18:52:39,370 - uvicorn.access - INFO - 172.20.0.1:58654 - "POST /api/v1/token/refresh HTTP/1.1" 401
2022-03-28 18:52:39,381 - uvicorn.access - INFO - 172.20.0.1:58652 - "POST /api/v1/token/refresh HTTP/1.1" 401
2022-03-28 18:52:39,385 - uvicorn.access - INFO - 172.20.0.1:58656 - "POST /api/v1/token/refresh HTTP/1.1" 401
